Workbook

Sheet Deckblatt
B2: Finanzplanung No.1 Fitness & HYROX Studio (Arbeitstitel)
B3: Businessplan-Anlage: Kapitalbedarf, Finanzierungsplan, Mitglieder-/Umsatz-/Kostenplanung, Liquiditätsplan, Rentabilitätsvorschau (5 Jahre)
B4: Stand: 27.09.2026 · Grundlage: Planung „No.1 (überarbeitet)“ aus GymPlanner (1975 m² Bruttofläche), Kaltmiete 8.50 €/m², Anlaufreserve für 24 Monate
B6: Legende
B7: Blaue Schrift | C7: Eingabewert / Annahme – darf geändert werden (Blatt „Annahmen“, „Investition“)
B8: Schwarze Schrift | C8: Formel – nicht überschreiben
B9: Grüne Schrift | C9: Verweis auf ein anderes Blatt
B10: Gelbe Füllung | C10: Vor dem Bankgespräch prüfen bzw. persönlich ausfüllen (Eigenkapital, Gründerdaten, Eröffnungstermin)
B12: Blätter
B13: Annahmen | C13: Alle Eingaben: Fläche, Miete, Tarife, Mitgliederentwicklung, Personal, Sachkosten, Finanzierung, Steuern, Szenario-Schalter
B14: Investition | C14: Kapitalbedarf: Geräte je Bereich (Stückliste GymPlanner), Ausbau, Sanitär, Planung, Unvorhergesehenes, Kaution, Gründung, Anlaufreserve; Zahlungsplan Vorlaufmonate
B15: Finanzierung | C15: Mittelherkunft (Eigenkapital, Darlehen), Tilgungspläne je Darlehen (monatlich), Kapitaldienst je Jahr
B16: Mitglieder | C16: Neuzugänge, Kündigungen, Bestand je Monat (60 Monate), Spitzenlast gegen Kapazität
B17: Umsatz | C17: Beiträge, Servicepauschale, Aufnahmegebühren, Nebenumsätze – netto je Monat, Umsatzsteuer
B18: Kosten | C18: Personal (Stellenplan), Raumkosten, Marketing, sonstige Sachkosten je Monat inkl. Vorlaufphase, Vorsteuer
B19: Liquiditaet | C19: Monatlicher Liquiditätsplan von der Ausbauphase bis Monat 60 inkl. Umsatzsteuer-Zahllast/-Erstattung, Kapitaldienst, Steuern
B20: GuV | C20: Rentabilitätsvorschau Jahr 1–5, Kapitaldienstfähigkeit (DSCR), Abschreibungen, Steuern mit Verlustvortrag
B21: Kennzahlen | C21: Break-even (Mitglieder/Monat), Mindestliquidität, Reservebedarf, Quoten
B22: Szenarien | C22: Vergleich pessimistisch / Basis / optimistisch (Werte, erzeugt durch Umschalten der Zelle „Szenario“)
B25: Hinweise
B26: 1. | C26: Alle Beträge in Euro netto (ohne Umsatzsteuer), sofern nicht „brutto“ angegeben. Mitgliedsbeiträge sind Bruttopreise inkl. 19 % USt; die Planung rechnet sie auf netto um.
B27: 2. | C27: Monatsraster: Monate −5 … −1 = Vorlauf (Ausbau, Vorverkauf), Monat 1 = Eröffnungsmonat, Jahr 1 = Vorlauf + Monate 1–12 (Rumpf-/erstes Geschäftsjahr).
B28: 3. | C28: Investitionsbeträge stammen aus der Kostenkalkulation der Planungssoftware (Stückliste mit recherchierten Netto-Listenpreisen, Ausbau-Richtwerte je m²). Sie sind vor Vertragsabschluss durch Angebote zu ersetzen.
B29: 4. | C29: Die Anlaufreserve (Betriebsmittel) deckt die kumulierten Anlaufverluste der ersten 24 Monate inkl. Sicherheitspuffer; Blatt „Kennzahlen“ zeigt den berechneten Bedarf gegenüber dem angesetzten Betrag.
B30: 5. | C30: Darlehenskonditionen sind Planannahmen auf Basis der veröffentlichten Programmbedingungen (KfW/L-Bank/Bürgschaftsbank); die Hausbank legt die Preisklasse fest.

Sheet Annahmen
B1: Annahmen (Eingaben)
B2: Blau = Eingabe. Gelb = vor dem Bankgespräch ausfüllen/prüfen. Quellen und Herleitung siehe Businessplan Kapitel „Finanzplanung“ und Spalte E.
B4: Projekt
B5: Bruttofläche (Mietfläche) | C5: 1975.4 | D5: m² | E5: aus Planung No.1 (überarbeitet): Hallenaußenmaß
B6: Nettofläche | C6: 1931.13 | D6: m² | E6: Innenfläche ohne Wände
B7: Trainingsfläche (Zonen + Kursraum) | C7: 1138.58 | D7: m² | E7: Basis der Personenzahl (9 m² je Person)
B8: Gleichzeitige Nutzer (Kapazität) | C8: 126 | D8: Pers. | E8: Trainingsfläche ÷ 9 m²
B9: Vorlaufmonate (Ausbau + Vorverkauf) | C9: 5 | D9: Monate | E9: Monate −5 … −1 vor Eröffnung
B10: Eröffnungstermin (geplant) | C10: 46631 | E10: Monat 1 der Planung
B11: Szenario (1 = pessimistisch, 2 = Basis, 3 = optimistisch) | C11: 2 | E11: schaltet Neuzugänge, Kündigungsquote und Beitragsniveau um (Tabelle unten)
B12: Miete und Nebenkosten
B13: Kaltmiete | C13: 8.5 | D13: €/m²/Monat | E13: Vorgabe: 8,50 €/m² (Hallen-/Sonderfläche, Region Bodensee/Stuttgart)
B14: Betriebskosten (Grundsteuer, Versicherung, Müll, Hausmeister) | C14: 2 | D14: €/m²/Monat
B15: Energie und Wasser (Strom, Wärme, Wasser/Abwasser) | C15: 4 | D15: €/m²/Monat | E15: inkl. Sauna/Dampfbad und Lüftung; erst ab Eröffnung
B16: Kaution | C16: 3 | D16: Monatsmieten | E16: inkl. Nebenkosten (Investition)
B17: Mietfreie Monate während des Ausbaus | C17: 3 | D17: Monate | E17: Verhandlungsziel Mietvertrag; danach Miete + Betriebskosten ab Übergabe
B18: Mietindexierung je Jahr | C18: 0.02 | D18: % p. a. | E18: Indexmiete, ab Jahr 2
B19: Vermieter optiert zur Umsatzsteuer (1 = ja, 0 = nein) | C19: 1 | E19: bei 1 ist die USt auf Miete/BK als Vorsteuer abziehbar
B20: Tarife (brutto inkl. USt) und Mitgliedermix
B21: Basic (Kraft, Cardio, Freihantel, Kurse) | C21: 44.9 | D21: €/Monat
B22: Anteil Basic am Bestand | C22: 0.4
B23: Premium (zusätzlich Wellness/Sauna/Dampfbad, HYROX-Zone, Getränke-Flat) | C23: 59.9 | D23: €/Monat
B24: Anteil Premium am Bestand | C24: 0.45
B25: Student/Azubi/Senior (Basic-Leistungen) | C25: 34.9 | D25: €/Monat
B26: Anteil Student/Azubi/Senior | C26: 0.15 | E26: Summe der Anteile = 100 %
B27: Servicepauschale je Halbjahr (brutto) | C27: 24.9 | D27: € | E27: branchenüblich (Trainings-/Servicepauschale), 0 = keine
B28: Aufnahmegebühr (brutto) | C28: 49 | D28: € | E28: einmalig je Neuzugang
B29: Anteil Neuzugänge, die Aufnahmegebühr zahlen | C29: 0.7 | E29: Rest über Aktionen erlassen
B30: Beitragsanpassung ab Jahr 3 | C30: 0.02 | D30: % p. a. | E30: auf den Bestand (Indexklausel)
B31: Umsatzsteuersatz | C31: 0.19 | E31: Fitnessleistungen 19 %
B32: Ø Beitrag je Mitglied und Monat (brutto, gewichteter Mix, Szenario) | C32: =(Beitrag_Basic*Anteil_Basic+Beitrag_Premium*Anteil_Premium+Beitrag_Student*Anteil_Student)*Beitrag_Faktor -> 50.15 | D32: €/Monat | E32: Formel
B33: Nebenumsätze je Mitglied und Monat (brutto)
B34: Getränke, Shakes, Riegel | C34: 3 | D34: €
B35: Wareneinsatz Getränke/Shakes | C35: 0.4 | D35: % vom Netto
B36: Solarium, Wellness-Zusatz, Getränke-Flat-Upgrade | C36: 1.2 | D36: €
B37: Personal Training, Zusatzkurse, Ernährungsberatung (Provisionsanteil) | C37: 1.5 | D37: €
B38: Merchandise, Sonstiges | C38: 0.5 | D38: €
B39: Mitgliederentwicklung
B40: Mitglieder zur Eröffnung (Vorverkauf, 3 Monate) | C40: 350 | D40: Mitgl. | E40: Basis-Szenario, wird mit Szenario-Faktor skaliert
B41: Neuzugänge je Monat, Monate 1–3 | C41: 140 | D41: Mitgl./Monat | E41: Eröffnungsphase
...

Sheet Investition
B1: Investition und Kapitalbedarf (netto, EUR)
B2: Gerätepositionen und Ausbau aus der GymPlanner-Kalkulation (Blatt-Quelle: Stückliste No.1, Miete 8,50 €/m²). Vor Vertragsabschluss durch Angebote ersetzen. Zahlungsplan rechts: Verteilung auf die Vorlaufmonate.
L3: Zahlungsplan (netto) je Monat
B4: Gruppe | C4: Position | D4: Betrag netto | E4: AfA Jahre | F4: AfA je Jahr | G4: Vorsteuer | H4: ab Monat | I4: Monate | J4: Hinweis | L4: Monat | M4: -5 | N4: -4 | O4: -3 | P4: -2 | Q4: -1 | R4: 1 | S4: 2 | T4: 3
B5: Geräte | C5: Geräte Kraftgeräte | D5: 268570 | E5: =AfA_Geraete -> 8 | F5: =IF(E5>0,D5/E5,0) -> 33571.25 | G5: 1 | H5: -1 | I5: 1 | J5: 52 Objekte lt. Stückliste | M5: =IF(AND(M$4>=$H5,M$4<$H5+$I5),$D5/$I5,0) -> 0 | N5: =IF(AND(N$4>=$H5,N$4<$H5+$I5),$D5/$I5,0) -> 0 | O5: =IF(AND(O$4>=$H5,O$4<$H5+$I5),$D5/$I5,0) -> 0 | P5: =IF(AND(P$4>=$H5,P$4<$H5+$I5),$D5/$I5,0) -> 0 | Q5: =IF(AND(Q$4>=$H5,Q$4<$H5+$I5),$D5/$I5,0) -> 268570 | R5: =IF(AND(R$4>=$H5,R$4<$H5+$I5),$D5/$I5,0) -> 0 | S5: =IF(AND(S$4>=$H5,S$4<$H5+$I5),$D5/$I5,0) -> 0 | T5: =IF(AND(T$4>=$H5,T$4<$H5+$I5),$D5/$I5,0) -> 0
B6: Geräte | C6: Geräte Freihantel-Zubehör | D6: 4300 | E6: =AfA_Geraete -> 8 | F6: =IF(E6>0,D6/E6,0) -> 537.5 | G6: 1 | H6: -1 | I6: 1 | J6: 10 Objekte lt. Stückliste | M6: =IF(AND(M$4>=$H6,M$4<$H6+$I6),$D6/$I6,0) -> 0 | N6: =IF(AND(N$4>=$H6,N$4<$H6+$I6),$D6/$I6,0) -> 0 | O6: =IF(AND(O$4>=$H6,O$4<$H6+$I6),$D6/$I6,0) -> 0 | P6: =IF(AND(P$4>=$H6,P$4<$H6+$I6),$D6/$I6,0) -> 0 | Q6: =IF(AND(Q$4>=$H6,Q$4<$H6+$I6),$D6/$I6,0) -> 4300 | R6: =IF(AND(R$4>=$H6,R$4<$H6+$I6),$D6/$I6,0) -> 0 | S6: =IF(AND(S$4>=$H6,S$4<$H6+$I6),$D6/$I6,0) -> 0 | T6: =IF(AND(T$4>=$H6,T$4<$H6+$I6),$D6/$I6,0) -> 0
B7: Geräte | C7: Geräte Cardio | D7: 104760 | E7: =AfA_Geraete -> 8 | F7: =IF(E7>0,D7/E7,0) -> 13095 | G7: 1 | H7: -1 | I7: 1 | J7: 20 Objekte lt. Stückliste | M7: =IF(AND(M$4>=$H7,M$4<$H7+$I7),$D7/$I7,0) -> 0 | N7: =IF(AND(N$4>=$H7,N$4<$H7+$I7),$D7/$I7,0) -> 0 | O7: =IF(AND(O$4>=$H7,O$4<$H7+$I7),$D7/$I7,0) -> 0 | P7: =IF(AND(P$4>=$H7,P$4<$H7+$I7),$D7/$I7,0) -> 0 | Q7: =IF(AND(Q$4>=$H7,Q$4<$H7+$I7),$D7/$I7,0) -> 104760 | R7: =IF(AND(R$4>=$H7,R$4<$H7+$I7),$D7/$I7,0) -> 0 | S7: =IF(AND(S$4>=$H7,S$4<$H7+$I7),$D7/$I7,0) -> 0 | T7: =IF(AND(T$4>=$H7,T$4<$H7+$I7),$D7/$I7,0) -> 0
B8: Geräte | C8: Geräte Functional | D8: 6709 | E8: =AfA_Geraete -> 8 | F8: =IF(E8>0,D8/E8,0) -> 838.625 | G8: 1 | H8: -1 | I8: 1 | J8: 22 Objekte lt. Stückliste | M8: =IF(AND(M$4>=$H8,M$4<$H8+$I8),$D8/$I8,0) -> 0 | N8: =IF(AND(N$4>=$H8,N$4<$H8+$I8),$D8/$I8,0) -> 0 | O8: =IF(AND(O$4>=$H8,O$4<$H8+$I8),$D8/$I8,0) -> 0 | P8: =IF(AND(P$4>=$H8,P$4<$H8+$I8),$D8/$I8,0) -> 0 | Q8: =IF(AND(Q$4>=$H8,Q$4<$H8+$I8),$D8/$I8,0) -> 6709 | R8: =IF(AND(R$4>=$H8,R$4<$H8+$I8),$D8/$I8,0) -> 0 | S8: =IF(AND(S$4>=$H8,S$4<$H8+$I8),$D8/$I8,0) -> 0 | T8: =IF(AND(T$4>=$H8,T$4<$H8+$I8),$D8/$I8,0) -> 0
B9: Geräte | C9: Geräte Kursraum | D9: 20610 | E9: =AfA_Geraete -> 8 | F9: =IF(E9>0,D9/E9,0) -> 2576.25 | G9: 1 | H9: -1 | I9: 1 | J9: 28 Objekte lt. Stückliste | M9: =IF(AND(M$4>=$H9,M$4<$H9+$I9),$D9/$I9,0) -> 0 | N9: =IF(AND(N$4>=$H9,N$4<$H9+$I9),$D9/$I9,0) -> 0 | O9: =IF(AND(O$4>=$H9,O$4<$H9+$I9),$D9/$I9,0) -> 0 | P9: =IF(AND(P$4>=$H9,P$4<$H9+$I9),$D9/$I9,0) -> 0 | Q9: =IF(AND(Q$4>=$H9,Q$4<$H9+$I9),$D9/$I9,0) -> 20610 | R9: =IF(AND(R$4>=$H9,R$4<$H9+$I9),$D9/$I9,0) -> 0 | S9: =IF(AND(S$4>=$H9,S$4<$H9+$I9),$D9/$I9,0) -> 0 | T9: =IF(AND(T$4>=$H9,T$4<$H9+$I9),$D9/$I9,0) -> 0
B10: Geräte | C10: Geräte Empfang & Lounge | D10: 25274 | E10: =AfA_Geraete -> 8 | F10: =IF(E10>0,D10/E10,0) -> 3159.25 | G10: 1 | H10: -1 | I10: 1 | J10: 28 Objekte lt. Stückliste | M10: =IF(AND(M$4>=$H10,M$4<$H10+$I10),$D10/$I10,0) -> 0 | N10: =IF(AND(N$4>=$H10,N$4<$H10+$I10),$D10/$I10,0) -> 0 | O10: =IF(AND(O$4>=$H10,O$4<$H10+$I10),$D10/$I10,0) -> 0 | P10: =IF(AND(P$4>=$H10,P$4<$H10+$I10),$D10/$I10,0) -> 0 | Q10: =IF(AND(Q$4>=$H10,Q$4<$H10+$I10),$D10/$I10,0) -> 25274 | R10: =IF(AND(R$4>=$H10,R$4<$H10+$I10),$D10/$I10,0) -> 0 | S10: =IF(AND(S$4>=$H10,S$4<$H10+$I10),$D10/$I10,0) -> 0 | T10: =IF(AND(T$4>=$H10,T$4<$H10+$I10),$D10/$I10,0) -> 0
B11: Geräte | C11: Geräte Umkleide | D11: 32310 | E11: =AfA_Geraete -> 8 | F11: =IF(E11>0,D11/E11,0) -> 4038.75 | G11: 1 | H11: -1 | I11: 1 | J11: 39 Objekte lt. Stückliste | M11: =IF(AND(M$4>=$H11,M$4<$H11+$I11),$D11/$I11,0) -> 0 | N11: =IF(AND(N$4>=$H11,N$4<$H11+$I11),$D11/$I11,0) -> 0 | O11: =IF(AND(O$4>=$H11,O$4<$H11+$I11),$D11/$I11,0) -> 0 | P11: =IF(AND(P$4>=$H11,P$4<$H11+$I11),$D11/$I11,0) -> 0 | Q11: =IF(AND(Q$4>=$H11,Q$4<$H11+$I11),$D11/$I11,0) -> 32310 | R11: =IF(AND(R$4>=$H11,R$4<$H11+$I11),$D11/$I11,0) -> 0 | S11: =IF(AND(S$4>=$H11,S$4<$H11+$I11),$D11/$I11,0) -> 0 | T11: =IF(AND(T$4>=$H11,T$4<$H11+$I11),$D11/$I11,0) -> 0
B12: Geräte | C12: Geräte Sanitär | D12: 26250 | E12: =AfA_Geraete -> 8 | F12: =IF(E12>0,D12/E12,0) -> 3281.25 | G12: 1 | H12: -1 | I12: 1 | J12: 18 Objekte lt. Stückliste | M12: =IF(AND(M$4>=$H12,M$4<$H12+$I12),$D12/$I12,0) -> 0 | N12: =IF(AND(N$4>=$H12,N$4<$H12+$I12),$D12/$I12,0) -> 0 | O12: =IF(AND(O$4>=$H12,O$4<$H12+$I12),$D12/$I12,0) -> 0 | P12: =IF(AND(P$4>=$H12,P$4<$H12+$I12),$D12/$I12,0) -> 0 | Q12: =IF(AND(Q$4>=$H12,Q$4<$H12+$I12),$D12/$I12,0) -> 26250 | R12: =IF(AND(R$4>=$H12,R$4<$H12+$I12),$D12/$I12,0) -> 0 | S12: =IF(AND(S$4>=$H12,S$4<$H12+$I12),$D12/$I12,0) -> 0 | T12: =IF(AND(T$4>=$H12,T$4<$H12+$I12),$D12/$I12,0) -> 0
B13: Geräte | C13: Geräte Wellness | D13: 55850 | E13: =AfA_Geraete -> 8 | F13: =IF(E13>0,D13/E13,0) -> 6981.25 | G13: 1 | H13: -1 | I13: 1 | J13: 8 Objekte lt. Stückliste | M13: =IF(AND(M$4>=$H13,M$4<$H13+$I13),$D13/$I13,0) -> 0 | N13: =IF(AND(N$4>=$H13,N$4<$H13+$I13),$D13/$I13,0) -> 0 | O13: =IF(AND(O$4>=$H13,O$4<$H13+$I13),$D13/$I13,0) -> 0 | P13: =IF(AND(P$4>=$H13,P$4<$H13+$I13),$D13/$I13,0) -> 0 | Q13: =IF(AND(Q$4>=$H13,Q$4<$H13+$I13),$D13/$I13,0) -> 55850 | R13: =IF(AND(R$4>=$H13,R$4<$H13+$I13),$D13/$I13,0) -> 0 | S13: =IF(AND(S$4>=$H13,S$4<$H13+$I13),$D13/$I13,0) -> 0 | T13: =IF(AND(T$4>=$H13,T$4<$H13+$I13),$D13/$I13,0) -> 0
B14: Geräte | C14: Geräte Büro & Personal | D14: 5450 | E14: =AfA_Geraete -> 8 | F14: =IF(E14>0,D14/E14,0) -> 681.25 | G14: 1 | H14: -1 | I14: 1 | J14: 12 Objekte lt. Stückliste | M14: =IF(AND(M$4>=$H14,M$4<$H14+$I14),$D14/$I14,0) -> 0 | N14: =IF(AND(N$4>=$H14,N$4<$H14+$I14),$D14/$I14,0) -> 0 | O14: =IF(AND(O$4>=$H14,O$4<$H14+$I14),$D14/$I14,0) -> 0 | P14: =IF(AND(P$4>=$H14,P$4<$H14+$I14),$D14/$I14,0) -> 0 | Q14: =IF(AND(Q$4>=$H14,Q$4<$H14+$I14),$D14/$I14,0) -> 5450 | R14: =IF(AND(R$4>=$H14,R$4<$H14+$I14),$D14/$I14,0) -> 0 | S14: =IF(AND(S$4>=$H14,S$4<$H14+$I14),$D14/$I14,0) -> 0 | T14: =IF(AND(T$4>=$H14,T$4<$H14+$I14),$D14/$I14,0) -> 0
B15: Geräte | C15: Geräte Lager & Technik | D15: 8850 | E15: =AfA_Geraete -> 8 | F15: =IF(E15>0,D15/E15,0) -> 1106.25 | G15: 1 | H15: -1 | I15: 1 | J15: 14 Objekte lt. Stückliste | M15: =IF(AND(M$4>=$H15,M$4<$H15+$I15),$D15/$I15,0) -> 0 | N15: =IF(AND(N$4>=$H15,N$4<$H15+$I15),$D15/$I15,0) -> 0 | O15: =IF(AND(O$4>=$H15,O$4<$H15+$I15),$D15/$I15,0) -> 0 | P15: =IF(AND(P$4>=$H15,P$4<$H15+$I15),$D15/$I15,0) -> 0 | Q15: =IF(AND(Q$4>=$H15,Q$4<$H15+$I15),$D15/$I15,0) -> 8850 | R15: =IF(AND(R$4>=$H15,R$4<$H15+$I15),$D15/$I15,0) -> 0 | S15: =IF(AND(S$4>=$H15,S$4<$H15+$I15),$D15/$I15,0) -> 0 | T15: =IF(AND(T$4>=$H15,T$4<$H15+$I15),$D15/$I15,0) -> 0
B16: Geräte | C16: Geräte Ausstattung | D16: 32035 | E16: =AfA_Geraete -> 8 | F16: =IF(E16>0,D16/E16,0) -> 4004.375 | G16: 1 | H16: -1 | I16: 1 | J16: 111 Objekte lt. Stückliste | M16: =IF(AND(M$4>=$H16,M$4<$H16+$I16),$D16/$I16,0) -> 0 | N16: =IF(AND(N$4>=$H16,N$4<$H16+$I16),$D16/$I16,0) -> 0 | O16: =IF(AND(O$4>=$H16,O$4<$H16+$I16),$D16/$I16,0) -> 0 | P16: =IF(AND(P$4>=$H16,P$4<$H16+$I16),$D16/$I16,0) -> 0 | Q16: =IF(AND(Q$4>=$H16,Q$4<$H16+$I16),$D16/$I16,0) -> 32035 | R16: =IF(AND(R$4>=$H16,R$4<$H16+$I16),$D16/$I16,0) -> 0 | S16: =IF(AND(S$4>=$H16,S$4<$H16+$I16),$D16/$I16,0) -> 0 | T16: =IF(AND(T$4>=$H16,T$4<$H16+$I16),$D16/$I16,0) -> 0
B17: Geräte | C17: Import-Nebenkosten (Fracht, Zoll) Atlantis/Prime | D17: 32228 | E17: =AfA_Geraete -> 8 | F17: =IF(E17>0,D17/E17,0) -> 4028.5 | G17: 0 | H17: -1 | I17: 1 | J17: Fracht, Zoll, EUSt auf Atlantis/Prime-Geräte | M17: =IF(AND(M$4>=$H17,M$4<$H17+$I17),$D17/$I17,0) -> 0 | N17: =IF(AND(N$4>=$H17,N$4<$H17+$I17),$D17/$I17,0) -> 0 | O17: =IF(AND(O$4>=$H17,O$4<$H17+$I17),$D17/$I17,0) -> 0 | P17: =IF(AND(P$4>=$H17,P$4<$H17+$I17),$D17/$I17,0) -> 0 | Q17: =IF(AND(Q$4>=$H17,Q$4<$H17+$I17),$D17/$I17,0) -> 32228 | R17: =IF(AND(R$4>=$H17,R$4<$H17+$I17),$D17/$I17,0) -> 0 | S17: =IF(AND(S$4>=$H17,S$4<$H17+$I17),$D17/$I17,0) -> 0 | T17: =IF(AND(T$4>=$H17,T$4<$H17+$I17),$D17/$I17,0) -> 0
B18: Ausbau | C18: Grundausbau (Trockenbau, Elektro, LED, Heizung, Maler) | D18: 482784 | E18: =AfA_Ausbau -> 10 | F18: =IF(E18>0,D18/E18,0) -> 48278.4 | G18: 1 | H18: -4 | I18: 4 | J18: 1931 m² × 250 € | M18: =IF(AND(M$4>=$H18,M$4<$H18+$I18),$D18/$I18,0) -> 0 | N18: =IF(AND(N$4>=$H18,N$4<$H18+$I18),$D18/$I18,0) -> 120696 | O18: =IF(AND(O$4>=$H18,O$4<$H18+$I18),$D18/$I18,0) -> 120696 | P18: =IF(AND(P$4>=$H18,P$4<$H18+$I18),$D18/$I18,0) -> 120696 | Q18: =IF(AND(Q$4>=$H18,Q$4<$H18+$I18),$D18/$I18,0) -> 120696 | R18: =IF(AND(R$4>=$H18,R$4<$H18+$I18),$D18/$I18,0) -> 0 | S18: =IF(AND(S$4>=$H18,S$4<$H18+$I18),$D18/$I18,0) -> 0 | T18: =IF(AND(T$4>=$H18,T$4<$H18+$I18),$D18/$I18,0) -> 0
B19: Ausbau | C19: Sportboden Trainingsfläche | D19: 62622 | E19: =AfA_Ausbau -> 10 | F19: =IF(E19>0,D19/E19,0) -> 6262.2 | G19: 1 | H19: -4 | I19: 4 | J19: 1139 m² × 55 € | M19: =IF(AND(M$4>=$H19,M$4<$H19+$I19),$D19/$I19,0) -> 0 | N19: =IF(AND(N$4>=$H19,N$4<$H19+$I19),$D19/$I19,0) -> 15655.5 | O19: =IF(AND(O$4>=$H19,O$4<$H19+$I19),$D19/$I19,0) -> 15655.5 | P19: =IF(AND(P$4>=$H19,P$4<$H19+$I19),$D19/$I19,0) -> 15655.5 | Q19: =IF(AND(Q$4>=$H19,Q$4<$H19+$I19),$D19/$I19,0) -> 15655.5 | R19: =IF(AND(R$4>=$H19,R$4<$H19+$I19),$D19/$I19,0) -> 0 | S19: =IF(AND(S$4>=$H19,S$4<$H19+$I19),$D19/$I19,0) -> 0 | T19: =IF(AND(T$4>=$H19,T$4<$H19+$I19),$D19/$I19,0) -> 0
B20: Ausbau | C20: Nassbereich-Boden Umkleide/Sanitär | D20: 14309 | E20: =AfA_Ausbau -> 10 | F20: =IF(E20>0,D20/E20,0) -> 1430.9 | G20: 1 | H20: -4 | I20: 4 | J20: 159 m² × 90 € | M20: =IF(AND(M$4>=$H20,M$4<$H20+$I20),$D20/$I20,0) -> 0 | N20: =IF(AND(N$4>=$H20,N$4<$H20+$I20),$D20/$I20,0) -> 3577.25 | O20: =IF(AND(O$4>=$H20,O$4<$H20+$I20),$D20/$I20,0) -> 3577.25 | P20: =IF(AND(P$4>=$H20,P$4<$H20+$I20),$D20/$I20,0) -> 3577.25 | Q20: =IF(AND(Q$4>=$H20,Q$4<$H20+$I20),$D20/$I20,0) -> 3577.25 | R20: =IF(AND(R$4>=$H20,R$4<$H20+$I20),$D20/$I20,0) -> 0 | S20: =IF(AND(S$4>=$H20,S$4<$H20+$I20),$D20/$I20,0) -> 0 | T20: =IF(AND(T$4>=$H20,T$4<$H20+$I20),$D20/$I20,0) -> 0
B21: Ausbau | C21: Lüftung (RLT-Anlage) | D21: 212425 | E21: =AfA_Ausbau -> 10 | F21: =IF(E21>0,D21/E21,0) -> 21242.5 | G21: 1 | H21: -4 | I21: 4 | J21: 1931 m² × 110 € | M21: =IF(AND(M$4>=$H21,M$4<$H21+$I21),$D21/$I21,0) -> 0 | N21: =IF(AND(N$4>=$H21,N$4<$H21+$I21),$D21/$I21,0) -> 53106.25 | O21: =IF(AND(O$4>=$H21,O$4<$H21+$I21),$D21/$I21,0) -> 53106.25 | P21: =IF(AND(P$4>=$H21,P$4<$H21+$I21),$D21/$I21,0) -> 53106.25 | Q21: =IF(AND(Q$4>=$H21,Q$4<$H21+$I21),$D21/$I21,0) -> 53106.25 | R21: =IF(AND(R$4>=$H21,R$4<$H21+$I21),$D21/$I21,0) -> 0 | S21: =IF(AND(S$4>=$H21,S$4<$H21+$I21),$D21/$I21,0) -> 0 | T21: =IF(AND(T$4>=$H21,T$4<$H21+$I21),$D21/$I21,0) -> 0
B22: Ausbau | C22: Spiegelwände | D22: 21714 | E22: =AfA_Ausbau -> 10 | F22: =IF(E22>0,D22/E22,0) -> 2171.4 | G22: 1 | H22: -4 | I22: 4 | J22: 33 m × 660 € | M22: =IF(AND(M$4>=$H22,M$4<$H22+$I22),$D22/$I22,0) -> 0 | N22: =IF(AND(N$4>=$H22,N$4<$H22+$I22),$D22/$I22,0) -> 5428.5 | O22: =IF(AND(O$4>=$H22,O$4<$H22+$I22),$D22/$I22,0) -> 5428.5 | P22: =IF(AND(P$4>=$H22,P$4<$H22+$I22),$D22/$I22,0) -> 5428.5 | Q22: =IF(AND(Q$4>=$H22,Q$4<$H22+$I22),$D22/$I22,0) -> 5428.5 | R22: =IF(AND(R$4>=$H22,R$4<$H22+$I22),$D22/$I22,0) -> 0 | S22: =IF(AND(S$4>=$H22,S$4<$H22+$I22),$D22/$I22,0) -> 0 | T22: =IF(AND(T$4>=$H22,T$4<$H22+$I22),$D22/$I22,0) -> 0
B23: Ausbau | C23: Brandschutz / Sicherheitsbeleuchtung | D23: 57934 | E23: =AfA_Ausbau -> 10 | F23: =IF(E23>0,D23/E23,0) -> 5793.4 | G23: 1 | H23: -4 | I23: 4 | J23: 1931 m² × 30 € | M23: =IF(AND(M$4>=$H23,M$4<$H23+$I23),$D23/$I23,0) -> 0 | N23: =IF(AND(N$4>=$H23,N$4<$H23+$I23),$D23/$I23,0) -> 14483.5 | O23: =IF(AND(O$4>=$H23,O$4<$H23+$I23),$D23/$I23,0) -> 14483.5 | P23: =IF(AND(P$4>=$H23,P$4<$H23+$I23),$D23/$I23,0) -> 14483.5 | Q23: =IF(AND(Q$4>=$H23,Q$4<$H23+$I23),$D23/$I23,0) -> 14483.5 | R23: =IF(AND(R$4>=$H23,R$4<$H23+$I23),$D23/$I23,0) -> 0 | S23: =IF(AND(S$4>=$H23,S$4<$H23+$I23),$D23/$I23,0) -> 0 | T23: =IF(AND(T$4>=$H23,T$4<$H23+$I23),$D23/$I23,0) -> 0
B24: Sanitär | C24: Sanitärinstallation Duschen | D24: 27000 | E24: =AfA_Ausbau -> 10 | F24: =IF(E24>0,D24/E24,0) -> 2700 | G24: 1 | H24: -4 | I24: 4 | J24: 18 Stk. × 1500 € | M24: =IF(AND(M$4>=$H24,M$4<$H24+$I24),$D24/$I24,0) -> 0 | N24: =IF(AND(N$4>=$H24,N$4<$H24+$I24),$D24/$I24,0) -> 6750 | O24: =IF(AND(O$4>=$H24,O$4<$H24+$I24),$D24/$I24,0) -> 6750 | P24: =IF(AND(P$4>=$H24,P$4<$H24+$I24),$D24/$I24,0) -> 6750 | Q24: =IF(AND(Q$4>=$H24,Q$4<$H24+$I24),$D24/$I24,0) -> 6750 | R24: =IF(AND(R$4>=$H24,R$4<$H24+$I24),$D24/$I24,0) -> 0 | S24: =IF(AND(S$4>=$H24,S$4<$H24+$I24),$D24/$I24,0) -> 0 | T24: =IF(AND(T$4>=$H24,T$4<$H24+$I24),$D24/$I24,0) -> 0
B25: Sanitär | C25: Sanitärinstallation WCs/Urinale | D25: 8800 | E25: =AfA_Ausbau -> 10 | F25: =IF(E25>0,D25/E25,0) -> 880 | G25: 1 | H25: -4 | I25: 4 | J25: 11 Stk. × 800 € | M25: =IF(AND(M$4>=$H25,M$4<$H25+$I25),$D25/$I25,0) -> 0 | N25: =IF(AND(N$4>=$H25,N$4<$H25+$I25),$D25/$I25,0) -> 2200 | O25: =IF(AND(O$4>=$H25,O$4<$H25+$I25),$D25/$I25,0) -> 2200 | P25: =IF(AND(P$4>=$H25,P$4<$H25+$I25),$D25/$I25,0) -> 2200 | Q25: =IF(AND(Q$4>=$H25,Q$4<$H25+$I25),$D25/$I25,0) -> 2200 | R25: =IF(AND(R$4>=$H25,R$4<$H25+$I25),$D25/$I25,0) -> 0 | S25: =IF(AND(S$4>=$H25,S$4<$H25+$I25),$D25/$I25,0) -> 0 | T25: =IF(AND(T$4>=$H25,T$4<$H25+$I25),$D25/$I25,0) -> 0
B26: Sanitär | C26: Sanitärinstallation Waschtische | D26: 4000 | E26: =AfA_Ausbau -> 10 | F26: =IF(E26>0,D26/E26,0) -> 400 | G26: 1 | H26: -4 | I26: 4 | J26: 8 Stk. × 500 € | M26: =IF(AND(M$4>=$H26,M$4<$H26+$I26),$D26/$I26,0) -> 0 | N26: =IF(AND(N$4>=$H26,N$4<$H26+$I26),$D26/$I26,0) -> 1000 | O26: =IF(AND(O$4>=$H26,O$4<$H26+$I26),$D26/$I26,0) -> 1000 | P26: =IF(AND(P$4>=$H26,P$4<$H26+$I26),$D26/$I26,0) -> 1000 | Q26: =IF(AND(Q$4>=$H26,Q$4<$H26+$I26),$D26/$I26,0) -> 1000 | R26: =IF(AND(R$4>=$H26,R$4<$H26+$I26),$D26/$I26,0) -> 0 | S26: =IF(AND(S$4>=$H26,S$4<$H26+$I26),$D26/$I26,0) -> 0 | T26: =IF(AND(T$4>=$H26,T$4<$H26+$I26),$D26/$I26,0) -> 0
B27: Planung | C27: Planung, Fachplaner, Genehmigung (Nutzungsänderung) | D27: 106991 | E27: =AfA_Ausbau -> 10 | F27: =IF(E27>0,D27/E27,0) -> 10699.1 | G27: 1 | H27: -5 | I27: 5 | J27: Prozent der Ausbau- und Sanitärsumme | M27: =IF(AND(M$4>=$H27,M$4<$H27+$I27),$D27/$I27,0) -> 21398.2 | N27: =IF(AND(N$4>=$H27,N$4<$H27+$I27),$D27/$I27,0) -> 21398.2 | O27: =IF(AND(O$4>=$H27,O$4<$H27+$I27),$D27/$I27,0) -> 21398.2 | P27: =IF(AND(P$4>=$H27,P$4<$H27+$I27),$D27/$I27,0) -> 21398.2 | Q27: =IF(AND(Q$4>=$H27,Q$4<$H27+$I27),$D27/$I27,0) -> 21398.2 | R27: =IF(AND(R$4>=$H27,R$4<$H27+$I27),$D27/$I27,0) -> 0 | S27: =IF(AND(S$4>=$H27,S$4<$H27+$I27),$D27/$I27,0) -> 0 | T27: =IF(AND(T$4>=$H27,T$4<$H27+$I27),$D27/$I27,0) -> 0
B28: Sonstiges | C28: Zutrittssystem, Studiosoftware-Einrichtung, Kleinmaterial, Brandschutzkonzept | D28: 32000 | E28: =AfA_Sonst -> 5 | F28: =IF(E28>0,D28/E28,0) -> 6400 | G28: 1 | H28: -2 | I28: 1 | J28: Marketing, Software, Kleinmaterial | M28: =IF(AND(M$4>=$H28,M$4<$H28+$I28),$D28/$I28,0) -> 0 | N28: =IF(AND(N$4>=$H28,N$4<$H28+$I28),$D28/$I28,0) -> 0 | O28: =IF(AND(O$4>=$H28,O$4<$H28+$I28),$D28/$I28,0) -> 0 | P28: =IF(AND(P$4>=$H28,P$4<$H28+$I28),$D28/$I28,0) -> 32000 | Q28: =IF(AND(Q$4>=$H28,Q$4<$H28+$I28),$D28/$I28,0) -> 0 | R28: =IF(AND(R$4>=$H28,R$4<$H28+$I28),$D28/$I28,0) -> 0 | S28: =IF(AND(S$4>=$H28,S$4<$H28+$I28),$D28/$I28,0) -> 0 | T28: =IF(AND(T$4>=$H28,T$4<$H28+$I28),$D28/$I28,0) -> 0
B29: Reserve | C29: Unvorhergesehenes (10 % der Investitionssumme) | D29: =ROUND(Unvorh_Pct*SUM(D5:D28),0) -> 165378 | E29: =AfA_Ausbau -> 10 | F29: =IF(E29>0,D29/E29,0) -> 16537.8 | G29: 1 | H29: -4 | I29: 4 | J29: Reserve für Mehrkosten im Ausbau | M29: =IF(AND(M$4>=$H29,M$4<$H29+$I29),$D29/$I29,0) -> 0 | N29: =IF(AND(N$4>=$H29,N$4<$H29+$I29),$D29/$I29,0) -> 41344.5 | O29: =IF(AND(O$4>=$H29,O$4<$H29+$I29),$D29/$I29,0) -> 41344.5 | P29: =IF(AND(P$4>=$H29,P$4<$H29+$I29),$D29/$I29,0) -> 41344.5 | Q29: =IF(AND(Q$4>=$H29,Q$4<$H29+$I29),$D29/$I29,0) -> 41344.5 | R29: =IF(AND(R$4>=$H29,R$4<$H29+$I29),$D29/$I29,0) -> 0 | S29: =IF(AND(S$4>=$H29,S$4<$H29+$I29),$D29/$I29,0) -> 0 | T29: =IF(AND(T$4>=$H29,T$4<$H29+$I29),$D29/$I29,0) -> 0
B30: Kaution | C30: Mietkaution (3 Monatsmieten inkl. Nebenkosten) | D30: =ROUND(Kaution_Monate*(Miete_kalt+BK+Energie)*Flaeche,0) -> 85930 | E30: 0 | F30: =IF(E30>0,D30/E30,0) -> 0 | G30: 0 | H30: -5 | I30: 1 | J30: Sicherheitsleistung, kein Aufwand | M30: =IF(AND(M$4>=$H30,M$4<$H30+$I30),$D30/$I30,0) -> 85930 | N30: =IF(AND(N$4>=$H30,N$4<$H30+$I30),$D30/$I30,0) -> 0 | O30: =IF(AND(O$4>=$H30,O$4<$H30+$I30),$D30/$I30,0) -> 0 | P30: =IF(AND(P$4>=$H30,P$4<$H30+$I30),$D30/$I30,0) -> 0 | Q30: =IF(AND(Q$4>=$H30,Q$4<$H30+$I30),$D30/$I30,0) -> 0 | R30: =IF(AND(R$4>=$H30,R$4<$H30+$I30),$D30/$I30,0) -> 0 | S30: =IF(AND(S$4>=$H30,S$4<$H30+$I30),$D30/$I30,0) -> 0 | T30: =IF(AND(T$4>=$H30,T$4<$H30+$I30),$D30/$I30,0) -> 0
B31: Gründung | C31: Gründungskosten GmbH (Notar, Handelsregister, Gewerbeanmeldung) | D31: =Gruendung -> 2500 | E31: 0 | F31: =IF(E31>0,D31/E31,0) -> 0 | G31: 1 | H31: -5 | I31: 1 | M31: =IF(AND(M$4>=$H31,M$4<$H31+$I31),$D31/$I31,0) -> 2500 | N31: =IF(AND(N$4>=$H31,N$4<$H31+$I31),$D31/$I31,0) -> 0 | O31: =IF(AND(O$4>=$H31,O$4<$H31+$I31),$D31/$I31,0) -> 0 | P31: =IF(AND(P$4>=$H31,P$4<$H31+$I31),$D31/$I31,0) -> 0 | Q31: =IF(AND(Q$4>=$H31,Q$4<$H31+$I31),$D31/$I31,0) -> 0 | R31: =IF(AND(R$4>=$H31,R$4<$H31+$I31),$D31/$I31,0) -> 0 | S31: =IF(AND(S$4>=$H31,S$4<$H31+$I31),$D31/$I31,0) -> 0 | T31: =IF(AND(T$4>=$H31,T$4<$H31+$I31),$D31/$I31,0) -> 0
B32: Gründung | C32: Beratung (Businessplan, Steuerberatung Gründung) | D32: =Beratung -> 5000 | E32: 0 | F32: =IF(E32>0,D32/E32,0) -> 0 | G32: 1 | H32: -5 | I32: 1 | M32: =IF(AND(M$4>=$H32,M$4<$H32+$I32),$D32/$I32,0) -> 5000 | N32: =IF(AND(N$4>=$H32,N$4<$H32+$I32),$D32/$I32,0) -> 0 | O32: =IF(AND(O$4>=$H32,O$4<$H32+$I32),$D32/$I32,0) -> 0 | P32: =IF(AND(P$4>=$H32,P$4<$H32+$I32),$D32/$I32,0) -> 0 | Q32: =IF(AND(Q$4>=$H32,Q$4<$H32+$I32),$D32/$I32,0) -> 0 | R32: =IF(AND(R$4>=$H32,R$4<$H32+$I32),$D32/$I32,0) -> 0 | S32: =IF(AND(S$4>=$H32,S$4<$H32+$I32),$D32/$I32,0) -> 0 | T32: =IF(AND(T$4>=$H32,T$4<$H32+$I32),$D32/$I32,0) -> 0
C33: Investitionssumme (ohne Anlaufreserve) | D33: =SUM(D5:D32) -> 1912583 | L33: Summe netto | M33: =SUM(M5:M32) -> 114828.2 | N33: =SUM(N5:N32) -> 285639.7 | O33: =SUM(O5:O32) -> 285639.7 | P33: =SUM(P5:P32) -> 317639.7 | Q33: =SUM(Q5:Q32) -> 908835.7 | R33: =SUM(R5:R32) -> 0 | S33: =SUM(S5:S32) -> 0 | T33: =SUM(T5:T32) -> 0
C34: Anlaufreserve / Betriebsmittel (24 Monate) | D34: =Reserve -> 710000 | L34: Vorsteuer | M34: =SUMPRODUCT(M5:M32,$G$5:$G$32)*UST -> 5490.658 | N34: =SUMPRODUCT(N5:N32,$G$5:$G$32)*UST -> 54271.543 | O34: =SUMPRODUCT(O5:O32,$G$5:$G$32)*UST -> 54271.543 | P34: =SUMPRODUCT(P5:P32,$G$5:$G$32)*UST -> 60351.543 | Q34: =SUMPRODUCT(Q5:Q32,$G$5:$G$32)*UST -> 166555.46 | R34: =SUMPRODUCT(R5:R32,$G$5:$G$32)*UST -> 0 | S34: =SUMPRODUCT(S5:S32,$G$5:$G$32)*UST -> 0 | T34: =SUMPRODUCT(T5:T32,$G$5:$G$32)*UST -> 0
C35: Kapitalbedarf gesamt | D35: =Inv_Summe+Reserve -> 2622583
C37: Gerätewert (Geräte + Import) – Basis Wartung | D37: =SUMIF(B5:B32,"Geräte",D5:D32) -> 623196
C38: Gründungs-/Beratungskosten (Aufwand Jahr 1) | D38: =SUMIF(B5:B32,"Gründung",D5:D32) -> 7500
C39: Umsatzsteuer auf Investitionen (Vorsteuer, wird erstattet – Zwischenfinanzierung) | D39: =SUMPRODUCT(D5:D32,G5:G32)*UST -> 340940.75
C41: Zusammenfassung je Gruppe
C42: Geräte | D42: =SUMIF($B$5:$B$32,"Geräte",$D$5:$D$32) -> 623196
...

Sheet Mitglieder
B1: Mitgliederentwicklung je Monat
B2: Bestand Ende = MIN(Obergrenze; Anfang + Neuzugänge − Kündigungen). Kündigungen = Anfangsbestand × Kündigungsquote. Monat 1 startet mit dem Vorverkaufsbestand.
B4: Monat | C4: 1 | D4: 2 | E4: 3 | F4: 4 | G4: 5 | H4: 6 | I4: 7 | J4: 8 | K4: 9 | L4: 10 | M4: 11 | N4: 12 | O4: 13 | P4: 14 | Q4: 15 | R4: 16 | S4: 17 | T4: 18 | U4: 19 | V4: 20 | W4: 21 | X4: 22 | Y4: 23 | Z4: 24 | AA4: 25 | AB4: 26 | AC4: 27 | AD4: 28 | AE4: 29 | AF4: 30 | AG4: 31 | AH4: 32 | AI4: 33 | AJ4: 34 | AK4: 35 | AL4: 36 | AM4: 37 | AN4: 38 | AO4: 39 | AP4: 40 | AQ4: 41 | AR4: 42 | AS4: 43 | AT4: 44 | AU4: 45 | AV4: 46 | AW4: 47 | AX4: 48 | AY4: 49 | AZ4: 50 | BA4: 51 | BB4: 52 | BC4: 53 | BD4: 54 | BE4: 55 | BF4: 56 | BG4: 57 | BH4: 58 | BI4: 59 | BJ4: 60
B5: Jahr | C5: =IF(C4<1,1,INT((C4-1)/12)+1) -> 1 | D5: =IF(D4<1,1,INT((D4-1)/12)+1) -> 1 | E5: =IF(E4<1,1,INT((E4-1)/12)+1) -> 1 | F5: =IF(F4<1,1,INT((F4-1)/12)+1) -> 1 | G5: =IF(G4<1,1,INT((G4-1)/12)+1) -> 1 | H5: =IF(H4<1,1,INT((H4-1)/12)+1) -> 1 | I5: =IF(I4<1,1,INT((I4-1)/12)+1) -> 1 | J5: =IF(J4<1,1,INT((J4-1)/12)+1) -> 1 | ... BJ5: =IF(BJ4<1,1,INT((BJ4-1)/12)+1) -> 5
B6: Periode | C6: 1 | D6: 2 | E6: 3 | F6: 4 | G6: 5 | H6: 6 | I6: 7 | J6: 8 | K6: 9 | L6: 10 | M6: 11 | N6: 12 | O6: 13 | P6: 14 | Q6: 15 | R6: 16 | S6: 17 | T6: 18 | U6: 19 | V6: 20 | W6: 21 | X6: 22 | Y6: 23 | Z6: 24 | AA6: 25 | AB6: 26 | AC6: 27 | AD6: 28 | AE6: 29 | AF6: 30 | AG6: 31 | AH6: 32 | AI6: 33 | AJ6: 34 | AK6: 35 | AL6: 36 | AM6: 37 | AN6: 38 | AO6: 39 | AP6: 40 | AQ6: 41 | AR6: 42 | AS6: 43 | AT6: 44 | AU6: 45 | AV6: 46 | AW6: 47 | AX6: 48 | AY6: 49 | AZ6: 50 | BA6: 51 | BB6: 52 | BC6: 53 | BD6: 54 | BE6: 55 | BF6: 56 | BG6: 57 | BH6: 58 | BI6: 59 | BJ6: 60
B7: Bestand Anfang | C7: =Vorverkauf*Neu_Faktor -> 350 | D7: =C10 -> 482.3 | E7: =D10 -> 611.6894 | F7: =E10 -> 738.23223 | G7: =F10 -> 821.99112 | H7: =G10 -> 903.90732 | I7: =H10 -> 984.02136 | J7: =I10 -> 1062.3729 | K7: =J10 -> 1139.0007 | ... BJ7: =BI10 -> 2200
B8: Neuzugänge | C8: =Neu_Faktor*IF(C$4<=3,Neu_1,IF(C$4<=12,Neu_2,IF(C$4<=24,Neu_3,IF(C$4<=36,Neu_4,Neu_5)))) -> 140 | D8: =Neu_Faktor*IF(D$4<=3,Neu_1,IF(D$4<=12,Neu_2,IF(D$4<=24,Neu_3,IF(D$4<=36,Neu_4,Neu_5)))) -> 140 | E8: =Neu_Faktor*IF(E$4<=3,Neu_1,IF(E$4<=12,Neu_2,IF(E$4<=24,Neu_3,IF(E$4<=36,Neu_4,Neu_5)))) -> 140 | F8: =Neu_Faktor*IF(F$4<=3,Neu_1,IF(F$4<=12,Neu_2,IF(F$4<=24,Neu_3,IF(F$4<=36,Neu_4,Neu_5)))) -> 100 | G8: =Neu_Faktor*IF(G$4<=3,Neu_1,IF(G$4<=12,Neu_2,IF(G$4<=24,Neu_3,IF(G$4<=36,Neu_4,Neu_5)))) -> 100 | H8: =Neu_Faktor*IF(H$4<=3,Neu_1,IF(H$4<=12,Neu_2,IF(H$4<=24,Neu_3,IF(H$4<=36,Neu_4,Neu_5)))) -> 100 | I8: =Neu_Faktor*IF(I$4<=3,Neu_1,IF(I$4<=12,Neu_2,IF(I$4<=24,Neu_3,IF(I$4<=36,Neu_4,Neu_5)))) -> 100 | J8: =Neu_Faktor*IF(J$4<=3,Neu_1,IF(J$4<=12,Neu_2,IF(J$4<=24,Neu_3,IF(J$4<=36,Neu_4,Neu_5)))) -> 100 | ... BJ8: =Neu_Faktor*IF(BJ$4<=3,Neu_1,IF(BJ$4<=12,Neu_2,IF(BJ$4<=24,Neu_3,IF(BJ$4<=36,Neu_4,Neu_5)))) -> 75
B9: Kündigungen | C9: =C7*Churn -> 7.7 | D9: =D7*Churn -> 10.6106 | E9: =E7*Churn -> 13.457167 | F9: =F7*Churn -> 16.241109 | G9: =G7*Churn -> 18.083805 | H9: =H7*Churn -> 19.885961 | I9: =I7*Churn -> 21.64847 | J9: =J7*Churn -> 23.372204 | ... BJ9: =BJ7*Churn -> 48.4
B10: Bestand Ende | C10: =MIN(Kapazitaet_Max,C7+C8-C9) -> 482.3 | D10: =MIN(Kapazitaet_Max,D7+D8-D9) -> 611.6894 | E10: =MIN(Kapazitaet_Max,E7+E8-E9) -> 738.23223 | F10: =MIN(Kapazitaet_Max,F7+F8-F9) -> 821.99112 | G10: =MIN(Kapazitaet_Max,G7+G8-G9) -> 903.90732 | H10: =MIN(Kapazitaet_Max,H7+H8-H9) -> 984.02136 | I10: =MIN(Kapazitaet_Max,I7+I8-I9) -> 1062.3729 | J10: =MIN(Kapazitaet_Max,J7+J8-J9) -> 1139.0007 | ... BJ10: =MIN(Kapazitaet_Max,BJ7+BJ8-BJ9) -> 2200
B11: Durchschnittsbestand (Abrechnungsbasis) | C11: =(C7+C10)/2 -> 416.15 | D11: =(D7+D10)/2 -> 546.9947 | E11: =(E7+E10)/2 -> 674.96082 | F11: =(F7+F10)/2 -> 780.11168 | G11: =(G7+G10)/2 -> 862.94922 | H11: =(H7+H10)/2 -> 943.96434 | I11: =(I7+I10)/2 -> 1023.1971 | J11: =(J7+J10)/2 -> 1100.6868 | ... BJ11: =(BJ7+BJ10)/2 -> 2200
B12: Gleichzeitig anwesend zur Spitzenzeit | C12: =C10*Spitzenlast -> 26.5265 | D12: =D10*Spitzenlast -> 33.642917 | E12: =E10*Spitzenlast -> 40.602773 | F12: =F10*Spitzenlast -> 45.209512 | G12: =G10*Spitzenlast -> 49.714903 | H12: =H10*Spitzenlast -> 54.121175 | I12: =I10*Spitzenlast -> 58.430509 | J12: =J10*Spitzenlast -> 62.645038 | ... BJ12: =BJ10*Spitzenlast -> 121
B13: Auslastung Spitzenzeit (gegen Kapazität) | C13: =C12/Personen -> 0.21052778 | D13: =D12/Personen -> 0.26700728 | E13: =E12/Personen -> 0.32224423 | F13: =F12/Personen -> 0.35880565 | G13: =G12/Personen -> 0.39456272 | H13: =H12/Personen -> 0.42953313 | I13: =I12/Personen -> 0.4637342 | J13: =J12/Personen -> 0.49718284 | ... BJ13: =BJ12/Personen -> 0.96031746
B16: Jahreswerte
B17: Jahr | C17: 1 | D17: 2 | E17: 3 | F17: 4 | G17: 5
B18: Neuzugänge im Jahr | C18: =SUMIF(Mg_Jahr,C17,Mg_Neu) -> 1320 | D18: =SUMIF(Mg_Jahr,D17,Mg_Neu) -> 1080 | E18: =SUMIF(Mg_Jahr,E17,Mg_Neu) -> 960 | F18: =SUMIF(Mg_Jahr,F17,Mg_Neu) -> 900 | G18: =SUMIF(Mg_Jahr,G17,Mg_Neu) -> 900
B19: Bestand am Jahresende | C19: =INDEX(Mg_Ende,C17*12) -> 1429.0206 | D19: =INDEX(Mg_Ende,D17*12) -> 2052.6653 | E19: =INDEX(Mg_Ende,E17*12) -> 2200 | F19: =INDEX(Mg_Ende,F17*12) -> 2200 | G19: =INDEX(Mg_Ende,G17*12) -> 2200
B20: Mitglieder je m² Bruttofläche | C20: =C19/Flaeche -> 0.72340821 | D20: =D19/Flaeche -> 1.0391138 | E20: =E19/Flaeche -> 1.1136985 | F20: =F19/Flaeche -> 1.1136985 | G20: =G19/Flaeche -> 1.1136985

Sheet Umsatz
B1: Umsatzplanung je Monat (netto, EUR)
B2: Beiträge = Durchschnittsbestand × Ø Beitrag brutto ÷ (1 + USt). Beitragsanpassung ab Jahr 3. Nebenumsätze je Mitglied und Monat.
B4: Monat | C4: 1 | D4: 2 | E4: 3 | F4: 4 | G4: 5 | H4: 6 | I4: 7 | J4: 8 | K4: 9 | L4: 10 | M4: 11 | N4: 12 | O4: 13 | P4: 14 | Q4: 15 | R4: 16 | S4: 17 | T4: 18 | U4: 19 | V4: 20 | W4: 21 | X4: 22 | Y4: 23 | Z4: 24 | AA4: 25 | AB4: 26 | AC4: 27 | AD4: 28 | AE4: 29 | AF4: 30 | AG4: 31 | AH4: 32 | AI4: 33 | AJ4: 34 | AK4: 35 | AL4: 36 | AM4: 37 | AN4: 38 | AO4: 39 | AP4: 40 | AQ4: 41 | AR4: 42 | AS4: 43 | AT4: 44 | AU4: 45 | AV4: 46 | AW4: 47 | AX4: 48 | AY4: 49 | AZ4: 50 | BA4: 51 | BB4: 52 | BC4: 53 | BD4: 54 | BE4: 55 | BF4: 56 | BG4: 57 | BH4: 58 | BI4: 59 | BJ4: 60
B5: Jahr | C5: =IF(C4<1,1,INT((C4-1)/12)+1) -> 1 | D5: =IF(D4<1,1,INT((D4-1)/12)+1) -> 1 | E5: =IF(E4<1,1,INT((E4-1)/12)+1) -> 1 | F5: =IF(F4<1,1,INT((F4-1)/12)+1) -> 1 | G5: =IF(G4<1,1,INT((G4-1)/12)+1) -> 1 | H5: =IF(H4<1,1,INT((H4-1)/12)+1) -> 1 | I5: =IF(I4<1,1,INT((I4-1)/12)+1) -> 1 | J5: =IF(J4<1,1,INT((J4-1)/12)+1) -> 1 | ... BJ5: =IF(BJ4<1,1,INT((BJ4-1)/12)+1) -> 5
B6: Periode | C6: 1 | D6: 2 | E6: 3 | F6: 4 | G6: 5 | H6: 6 | I6: 7 | J6: 8 | K6: 9 | L6: 10 | M6: 11 | N6: 12 | O6: 13 | P6: 14 | Q6: 15 | R6: 16 | S6: 17 | T6: 18 | U6: 19 | V6: 20 | W6: 21 | X6: 22 | Y6: 23 | Z6: 24 | AA6: 25 | AB6: 26 | AC6: 27 | AD6: 28 | AE6: 29 | AF6: 30 | AG6: 31 | AH6: 32 | AI6: 33 | AJ6: 34 | AK6: 35 | AL6: 36 | AM6: 37 | AN6: 38 | AO6: 39 | AP6: 40 | AQ6: 41 | AR6: 42 | AS6: 43 | AT6: 44 | AU6: 45 | AV6: 46 | AW6: 47 | AX6: 48 | AY6: 49 | AZ6: 50 | BA6: 51 | BB6: 52 | BC6: 53 | BD6: 54 | BE6: 55 | BF6: 56 | BG6: 57 | BH6: 58 | BI6: 59 | BJ6: 60
B7: Durchschnittsbestand | C7: =Mitglieder!C11 -> 416.15 | D7: =Mitglieder!D11 -> 546.9947 | E7: =Mitglieder!E11 -> 674.96082 | F7: =Mitglieder!F11 -> 780.11168 | G7: =Mitglieder!G11 -> 862.94922 | H7: =Mitglieder!H11 -> 943.96434 | I7: =Mitglieder!I11 -> 1023.1971 | J7: =Mitglieder!J11 -> 1100.6868 | ... BJ7: =Mitglieder!BJ11 -> 2200
B8: Ø Beitrag brutto (inkl. Anpassung) | C8: =ARPU_brutto*(1+Beitrag_Erhoehung)^MAX(0,C$5-2) -> 50.15 | D8: =ARPU_brutto*(1+Beitrag_Erhoehung)^MAX(0,D$5-2) -> 50.15 | E8: =ARPU_brutto*(1+Beitrag_Erhoehung)^MAX(0,E$5-2) -> 50.15 | F8: =ARPU_brutto*(1+Beitrag_Erhoehung)^MAX(0,F$5-2) -> 50.15 | G8: =ARPU_brutto*(1+Beitrag_Erhoehung)^MAX(0,G$5-2) -> 50.15 | H8: =ARPU_brutto*(1+Beitrag_Erhoehung)^MAX(0,H$5-2) -> 50.15 | I8: =ARPU_brutto*(1+Beitrag_Erhoehung)^MAX(0,I$5-2) -> 50.15 | J8: =ARPU_brutto*(1+Beitrag_Erhoehung)^MAX(0,J$5-2) -> 50.15 | ... BJ8: =ARPU_brutto*(1+Beitrag_Erhoehung)^MAX(0,BJ$5-2) -> 53.219581
B9: Mitgliedsbeiträge netto | C9: =C7*C8/(1+UST) -> 17537.75 | D9: =D7*D8/(1+UST) -> 23051.919 | E9: =E7*E8/(1+UST) -> 28444.777 | F9: =F7*F8/(1+UST) -> 32876.135 | G9: =G7*G8/(1+UST) -> 36367.146 | H9: =H7*H8/(1+UST) -> 39781.354 | I9: =I7*I8/(1+UST) -> 43120.45 | J9: =J7*J8/(1+UST) -> 46386.086 | ... BJ9: =BJ7*BJ8/(1+UST) -> 98389.142
B10: Servicepauschale netto | C10: =C7*Service_Halbjahr/6/(1+UST) -> 1451.2794 | D10: =D7*Service_Halbjahr/6/(1+UST) -> 1907.5866 | E10: =E7*Service_Halbjahr/6/(1+UST) -> 2353.8549 | F10: =F7*Service_Halbjahr/6/(1+UST) -> 2720.5575 | G10: =G7*Service_Halbjahr/6/(1+UST) -> 3009.4448 | H10: =H7*Service_Halbjahr/6/(1+UST) -> 3291.9765 | I10: =I7*Service_Halbjahr/6/(1+UST) -> 3568.2925 | J10: =J7*Service_Halbjahr/6/(1+UST) -> 3838.5296 | ... BJ10: =BJ7*Service_Halbjahr/6/(1+UST) -> 7672.2689
B11: Aufnahmegebühren netto | C11: =Mitglieder!C8*Aufnahme_Anteil*Aufnahme/(1+UST) -> 4035.2941 | D11: =Mitglieder!D8*Aufnahme_Anteil*Aufnahme/(1+UST) -> 4035.2941 | E11: =Mitglieder!E8*Aufnahme_Anteil*Aufnahme/(1+UST) -> 4035.2941 | F11: =Mitglieder!F8*Aufnahme_Anteil*Aufnahme/(1+UST) -> 2882.3529 | G11: =Mitglieder!G8*Aufnahme_Anteil*Aufnahme/(1+UST) -> 2882.3529 | H11: =Mitglieder!H8*Aufnahme_Anteil*Aufnahme/(1+UST) -> 2882.3529 | I11: =Mitglieder!I8*Aufnahme_Anteil*Aufnahme/(1+UST) -> 2882.3529 | J11: =Mitglieder!J8*Aufnahme_Anteil*Aufnahme/(1+UST) -> 2882.3529 | ... BJ11: =Mitglieder!BJ8*Aufnahme_Anteil*Aufnahme/(1+UST) -> 2161.7647
B12: Nebenumsatz Getränke/Shakes netto | C12: =C7*Neben_Getraenke/(1+UST) -> 1049.1176 | D12: =D7*Neben_Getraenke/(1+UST) -> 1378.9782 | E12: =E7*Neben_Getraenke/(1+UST) -> 1701.5819 | F12: =F7*Neben_Getraenke/(1+UST) -> 1966.6681 | G12: =G7*Neben_Getraenke/(1+UST) -> 2175.5022 | H12: =H7*Neben_Getraenke/(1+UST) -> 2379.742 | I12: =I7*Neben_Getraenke/(1+UST) -> 2579.4885 | J12: =J7*Neben_Getraenke/(1+UST) -> 2774.8406 | ... BJ12: =BJ7*Neben_Getraenke/(1+UST) -> 5546.2185
B13: Nebenumsatz Wellness/Solarium netto | C13: =C7*Neben_Wellness/(1+UST) -> 419.64706 | D13: =D7*Neben_Wellness/(1+UST) -> 551.59129 | E13: =E7*Neben_Wellness/(1+UST) -> 680.63276 | F13: =F7*Neben_Wellness/(1+UST) -> 786.66724 | G13: =G7*Neben_Wellness/(1+UST) -> 870.2009 | H13: =H7*Neben_Wellness/(1+UST) -> 951.89681 | I13: =I7*Neben_Wellness/(1+UST) -> 1031.7954 | J13: =J7*Neben_Wellness/(1+UST) -> 1109.9363 | ... BJ13: =BJ7*Neben_Wellness/(1+UST) -> 2218.4874
B14: Nebenumsatz PT/Kurse netto | C14: =C7*Neben_PT/(1+UST) -> 524.55882 | D14: =D7*Neben_PT/(1+UST) -> 689.48912 | E14: =E7*Neben_PT/(1+UST) -> 850.79095 | F14: =F7*Neben_PT/(1+UST) -> 983.33405 | G14: =G7*Neben_PT/(1+UST) -> 1087.7511 | H14: =H7*Neben_PT/(1+UST) -> 1189.871 | I14: =I7*Neben_PT/(1+UST) -> 1289.7443 | J14: =J7*Neben_PT/(1+UST) -> 1387.4203 | ... BJ14: =BJ7*Neben_PT/(1+UST) -> 2773.1092
B15: Nebenumsatz Merchandise netto | C15: =C7*Neben_Merch/(1+UST) -> 174.85294 | D15: =D7*Neben_Merch/(1+UST) -> 229.82971 | E15: =E7*Neben_Merch/(1+UST) -> 283.59698 | F15: =F7*Neben_Merch/(1+UST) -> 327.77802 | G15: =G7*Neben_Merch/(1+UST) -> 362.58371 | H15: =H7*Neben_Merch/(1+UST) -> 396.62367 | I15: =I7*Neben_Merch/(1+UST) -> 429.91476 | J15: =J7*Neben_Merch/(1+UST) -> 462.47344 | ... BJ15: =BJ7*Neben_Merch/(1+UST) -> 924.36975
B16: Umsatz gesamt netto | C16: =SUM(C9:C15) -> 25192.5 | D16: =SUM(D9:D15) -> 31844.689 | E16: =SUM(E9:E15) -> 38350.529 | F16: =SUM(F9:F15) -> 42543.493 | G16: =SUM(G9:G15) -> 46754.981 | H16: =SUM(H9:H15) -> 50873.817 | I16: =SUM(I9:I15) -> 54902.039 | J16: =SUM(J9:J15) -> 58841.639 | ... BJ16: =SUM(BJ9:BJ15) -> 119685.36
B17: Umsatzsteuer auf Umsatz | C17: =C16*UST -> 4786.575 | D17: =D16*UST -> 6050.4908 | E17: =E16*UST -> 7286.6005 | F17: =F16*UST -> 8083.2637 | G17: =G16*UST -> 8883.4465 | H17: =H16*UST -> 9666.0253 | I17: =I16*UST -> 10431.387 | J17: =J16*UST -> 11179.911 | ... BJ17: =BJ16*UST -> 22740.218
B18: Wareneinsatz Getränke/Shakes | C18: =C12*Neben_WE -> 419.64706 | D18: =D12*Neben_WE -> 551.59129 | E18: =E12*Neben_WE -> 680.63276 | F18: =F12*Neben_WE -> 786.66724 | G18: =G12*Neben_WE -> 870.2009 | H18: =H12*Neben_WE -> 951.89681 | I18: =I12*Neben_WE -> 1031.7954 | J18: =J12*Neben_WE -> 1109.9363 | ... BJ18: =BJ12*Neben_WE -> 2218.4874
B21: Jahreswerte (netto)
B22: Jahr | C22: 1 | D22: 2 | E22: 3 | F22: 4 | G22: 5
B23: Beiträge inkl. Servicepauschale | C23: =SUMIF(Um_Jahr,C22,Um_Beitrag)+SUMIF(Um_Jahr,C22,Um_Service) -> 524433.99 | D23: =SUMIF(Um_Jahr,D22,Um_Beitrag)+SUMIF(Um_Jahr,D22,Um_Service) -> 960756.01 | E23: =SUMIF(Um_Jahr,E22,Um_Beitrag)+SUMIF(Um_Jahr,E22,Um_Service) -> 1211917.7 | F23: =SUMIF(Um_Jahr,F22,Um_Beitrag)+SUMIF(Um_Jahr,F22,Um_Service) -> 1249586.5 | G23: =SUMIF(Um_Jahr,G22,Um_Beitrag)+SUMIF(Um_Jahr,G22,Um_Service) -> 1272736.9
B24: Aufnahmegebühren | C24: =SUMIF(Um_Jahr,C22,Um_Aufnahme) -> 38047.059 | D24: =SUMIF(Um_Jahr,D22,Um_Aufnahme) -> 31129.412 | E24: =SUMIF(Um_Jahr,E22,Um_Aufnahme) -> 27670.588 | F24: =SUMIF(Um_Jahr,F22,Um_Aufnahme) -> 25941.176 | G24: =SUMIF(Um_Jahr,G22,Um_Aufnahme) -> 25941.176
B25: Nebenumsätze | C25: =SUMIF(Um_Jahr,C22,Um_Gesamt)-C23-C24 -> 59880.124 | D25: =SUMIF(Um_Jahr,D22,Um_Gesamt)-D23-D24 -> 109699.58 | E25: =SUMIF(Um_Jahr,E22,Um_Gesamt)-E23-E24 -> 135867.67 | F25: =SUMIF(Um_Jahr,F22,Um_Gesamt)-F23-F24 -> 137546.22 | G25: =SUMIF(Um_Jahr,G22,Um_Gesamt)-G23-G24 -> 137546.22
B26: Umsatz gesamt | C26: =SUMIF(Um_Jahr,C22,Um_Gesamt) -> 622361.18 | D26: =SUMIF(Um_Jahr,D22,Um_Gesamt) -> 1101585 | E26: =SUMIF(Um_Jahr,E22,Um_Gesamt) -> 1375455.9 | F26: =SUMIF(Um_Jahr,F22,Um_Gesamt) -> 1413073.9 | G26: =SUMIF(Um_Jahr,G22,Um_Gesamt) -> 1436224.3
B27: Umsatz je m² Bruttofläche | C27: =C26/Flaeche -> 315.05577 | D27: =D26/Flaeche -> 557.65162 | E27: =E26/Flaeche -> 696.29236 | F27: =F26/Flaeche -> 715.3356 | G27: =G26/Flaeche -> 727.05494
B30: Hilfszeilen für Kennzahlen
B31: Betriebsergebnis (Umsatz − Kosten) ≥ 0 → 1 | C31: =IF(C16-Kosten!H23>=0,1,0) -> 0 | D31: =IF(D16-Kosten!I23>=0,1,0) -> 0 | E31: =IF(E16-Kosten!J23>=0,1,0) -> 0 | F31: =IF(F16-Kosten!K23>=0,1,0) -> 0 | G31: =IF(G16-Kosten!L23>=0,1,0) -> 0 | H31: =IF(H16-Kosten!M23>=0,1,0) -> 0 | I31: =IF(I16-Kosten!N23>=0,1,0) -> 0 | J31: =IF(J16-Kosten!O23>=0,1,0) -> 0 | ... BJ31: =IF(BJ16-Kosten!BO23>=0,1,0) -> 1
B32: Cashflow nach Kapitaldienst ≥ 0 → 1 | C32: =IF(C16-Kosten!H23-Finanzierung!H61-Finanzierung!H62>=0,1,0) -> 0 | D32: =IF(D16-Kosten!I23-Finanzierung!I61-Finanzierung!I62>=0,1,0) -> 0 | E32: =IF(E16-Kosten!J23-Finanzierung!J61-Finanzierung!J62>=0,1,0) -> 0 | F32: =IF(F16-Kosten!K23-Finanzierung!K61-Finanzierung!K62>=0,1,0) -> 0 | G32: =IF(G16-Kosten!L23-Finanzierung!L61-Finanzierung!L62>=0,1,0) -> 0 | H32: =IF(H16-Kosten!M23-Finanzierung!M61-Finanzierung!M62>=0,1,0) -> 0 | I32: =IF(I16-Kosten!N23-Finanzierung!N61-Finanzierung!N62>=0,1,0) -> 0 | J32: =IF(J16-Kosten!O23-Finanzierung!O61-Finanzierung!O62>=0,1,0) -> 0 | ... BJ32: =IF(BJ16-Kosten!BO23-Finanzierung!BO61-Finanzierung!BO62>=0,1,0) -> 1

Sheet Kosten
B1: Kostenplanung je Monat (netto, EUR) – Vorlauf und Betrieb
B2: Monate < 1 = Vorlauf (Ausbau, Vorverkauf): Miete nach mietfreier Zeit, Personal je Eintrittsmonat, Vorverkaufsmarketing; ab Monat 1 volle Betriebskosten.
B4: Monat | C4: -5 | D4: -4 | E4: -3 | F4: -2 | G4: -1 | H4: 1 | I4: 2 | J4: 3 | K4: 4 | L4: 5 | M4: 6 | N4: 7 | O4: 8 | P4: 9 | Q4: 10 | R4: 11 | S4: 12 | T4: 13 | U4: 14 | V4: 15 | W4: 16 | X4: 17 | Y4: 18 | Z4: 19 | AA4: 20 | AB4: 21 | AC4: 22 | AD4: 23 | AE4: 24 | AF4: 25 | AG4: 26 | AH4: 27 | AI4: 28 | AJ4: 29 | AK4: 30 | AL4: 31 | AM4: 32 | AN4: 33 | AO4: 34 | AP4: 35 | AQ4: 36 | AR4: 37 | AS4: 38 | AT4: 39 | AU4: 40 | AV4: 41 | AW4: 42 | AX4: 43 | AY4: 44 | AZ4: 45 | BA4: 46 | BB4: 47 | BC4: 48 | BD4: 49 | BE4: 50 | BF4: 51 | BG4: 52 | BH4: 53 | BI4: 54 | BJ4: 55 | BK4: 56 | BL4: 57 | BM4: 58 | BN4: 59 | BO4: 60 | BQ4: Vorsteuer (1/0)
B5: Jahr | C5: =IF(C4<1,1,INT((C4-1)/12)+1) -> 1 | D5: =IF(D4<1,1,INT((D4-1)/12)+1) -> 1 | E5: =IF(E4<1,1,INT((E4-1)/12)+1) -> 1 | F5: =IF(F4<1,1,INT((F4-1)/12)+1) -> 1 | G5: =IF(G4<1,1,INT((G4-1)/12)+1) -> 1 | H5: =IF(H4<1,1,INT((H4-1)/12)+1) -> 1 | I5: =IF(I4<1,1,INT((I4-1)/12)+1) -> 1 | J5: =IF(J4<1,1,INT((J4-1)/12)+1) -> 1 | ... BO5: =IF(BO4<1,1,INT((BO4-1)/12)+1) -> 5
B6: Periode | C6: 1 | D6: 2 | E6: 3 | F6: 4 | G6: 5 | H6: 6 | I6: 7 | J6: 8 | K6: 9 | L6: 10 | M6: 11 | N6: 12 | O6: 13 | P6: 14 | Q6: 15 | R6: 16 | S6: 17 | T6: 18 | U6: 19 | V6: 20 | W6: 21 | X6: 22 | Y6: 23 | Z6: 24 | AA6: 25 | AB6: 26 | AC6: 27 | AD6: 28 | AE6: 29 | AF6: 30 | AG6: 31 | AH6: 32 | AI6: 33 | AJ6: 34 | AK6: 35 | AL6: 36 | AM6: 37 | AN6: 38 | AO6: 39 | AP6: 40 | AQ6: 41 | AR6: 42 | AS6: 43 | AT6: 44 | AU6: 45 | AV6: 46 | AW6: 47 | AX6: 48 | AY6: 49 | AZ6: 50 | BA6: 51 | BB6: 52 | BC6: 53 | BD6: 54 | BE6: 55 | BF6: 56 | BG6: 57 | BH6: 58 | BI6: 59 | BJ6: 60 | BK6: 61 | BL6: 62 | BM6: 63 | BN6: 64 | BO6: 65
B7: Personal (AG-Brutto inkl. Sozialabgaben) | C7: =SUMPRODUCT((Pers_Ab<=C$4)*Pers_Anzahl*Pers_Brutto*(1+Pers_Mini*Mini_Abg+(1-Pers_Mini)*AG_Anteil))*(1+Steig)^MAX(0,C$5-1) -> 0 | D7: =SUMPRODUCT((Pers_Ab<=D$4)*Pers_Anzahl*Pers_Brutto*(1+Pers_Mini*Mini_Abg+(1-Pers_Mini)*AG_Anteil))*(1+Steig)^MAX(0,D$5-1) -> 0 | E7: =SUMPRODUCT((Pers_Ab<=E$4)*Pers_Anzahl*Pers_Brutto*(1+Pers_Mini*Mini_Abg+(1-Pers_Mini)*AG_Anteil))*(1+Steig)^MAX(0,E$5-1) -> 4245.5 | F7: =SUMPRODUCT((Pers_Ab<=F$4)*Pers_Anzahl*Pers_Brutto*(1+Pers_Mini*Mini_Abg+(1-Pers_Mini)*AG_Anteil))*(1+Steig)^MAX(0,F$5-1) -> 8612.3 | G7: =SUMPRODUCT((Pers_Ab<=G$4)*Pers_Anzahl*Pers_Brutto*(1+Pers_Mini*Mini_Abg+(1-Pers_Mini)*AG_Anteil))*(1+Steig)^MAX(0,G$5-1) -> 15890.3 | H7: =SUMPRODUCT((Pers_Ab<=H$4)*Pers_Anzahl*Pers_Brutto*(1+Pers_Mini*Mini_Abg+(1-Pers_Mini)*AG_Anteil))*(1+Steig)^MAX(0,H$5-1) -> 28533.024 | I7: =SUMPRODUCT((Pers_Ab<=I$4)*Pers_Anzahl*Pers_Brutto*(1+Pers_Mini*Mini_Abg+(1-Pers_Mini)*AG_Anteil))*(1+Steig)^MAX(0,I$5-1) -> 28533.024 | J7: =SUMPRODUCT((Pers_Ab<=J$4)*Pers_Anzahl*Pers_Brutto*(1+Pers_Mini*Mini_Abg+(1-Pers_Mini)*AG_Anteil))*(1+Steig)^MAX(0,J$5-1) -> 28533.024 | ... BO7: =SUMPRODUCT((Pers_Ab<=BO$4)*Pers_Anzahl*Pers_Brutto*(1+Pers_Mini*Mini_Abg+(1-Pers_Mini)*AG_Anteil))*(1+Steig)^MAX(0,BO$5-1) -> 35511.895 | BQ7: 0
B8: Kaltmiete | C8: =IF(AND(C$4<1,C$4+Vorlauf<Mietfrei),0,Flaeche*Miete_kalt*(1+Index_pa)^MAX(0,C$5-1)) -> 0 | D8: =IF(AND(D$4<1,D$4+Vorlauf<Mietfrei),0,Flaeche*Miete_kalt*(1+Index_pa)^MAX(0,D$5-1)) -> 0 | E8: =IF(AND(E$4<1,E$4+Vorlauf<Mietfrei),0,Flaeche*Miete_kalt*(1+Index_pa)^MAX(0,E$5-1)) -> 0 | F8: =IF(AND(F$4<1,F$4+Vorlauf<Mietfrei),0,Flaeche*Miete_kalt*(1+Index_pa)^MAX(0,F$5-1)) -> 16790.9 | G8: =IF(AND(G$4<1,G$4+Vorlauf<Mietfrei),0,Flaeche*Miete_kalt*(1+Index_pa)^MAX(0,G$5-1)) -> 16790.9 | H8: =IF(AND(H$4<1,H$4+Vorlauf<Mietfrei),0,Flaeche*Miete_kalt*(1+Index_pa)^MAX(0,H$5-1)) -> 16790.9 | I8: =IF(AND(I$4<1,I$4+Vorlauf<Mietfrei),0,Flaeche*Miete_kalt*(1+Index_pa)^MAX(0,I$5-1)) -> 16790.9 | J8: =IF(AND(J$4<1,J$4+Vorlauf<Mietfrei),0,Flaeche*Miete_kalt*(1+Index_pa)^MAX(0,J$5-1)) -> 16790.9 | ... BO8: =IF(AND(BO$4<1,BO$4+Vorlauf<Mietfrei),0,Flaeche*Miete_kalt*(1+Index_pa)^MAX(0,BO$5-1)) -> 18175.01 | BQ8: 1
B9: Betriebskosten | C9: =IF(AND(C$4<1,C$4+Vorlauf<Mietfrei),0,Flaeche*BK) -> 0 | D9: =IF(AND(D$4<1,D$4+Vorlauf<Mietfrei),0,Flaeche*BK) -> 0 | E9: =IF(AND(E$4<1,E$4+Vorlauf<Mietfrei),0,Flaeche*BK) -> 0 | F9: =IF(AND(F$4<1,F$4+Vorlauf<Mietfrei),0,Flaeche*BK) -> 3950.8 | G9: =IF(AND(G$4<1,G$4+Vorlauf<Mietfrei),0,Flaeche*BK) -> 3950.8 | H9: =IF(AND(H$4<1,H$4+Vorlauf<Mietfrei),0,Flaeche*BK) -> 3950.8 | I9: =IF(AND(I$4<1,I$4+Vorlauf<Mietfrei),0,Flaeche*BK) -> 3950.8 | J9: =IF(AND(J$4<1,J$4+Vorlauf<Mietfrei),0,Flaeche*BK) -> 3950.8 | ... BO9: =IF(AND(BO$4<1,BO$4+Vorlauf<Mietfrei),0,Flaeche*BK) -> 3950.8 | BQ9: 1
B10: Energie und Wasser | C10: =IF(C$4<1,0,Flaeche*Energie) -> 0 | D10: =IF(D$4<1,0,Flaeche*Energie) -> 0 | E10: =IF(E$4<1,0,Flaeche*Energie) -> 0 | F10: =IF(F$4<1,0,Flaeche*Energie) -> 0 | G10: =IF(G$4<1,0,Flaeche*Energie) -> 0 | H10: =IF(H$4<1,0,Flaeche*Energie) -> 7901.6 | I10: =IF(I$4<1,0,Flaeche*Energie) -> 7901.6 | J10: =IF(J$4<1,0,Flaeche*Energie) -> 7901.6 | ... BO10: =IF(BO$4<1,0,Flaeche*Energie) -> 7901.6 | BQ10: 1
B11: Marketing (laufend, Eröffnung, Vorverkauf) | C11: =IF(C$4+Vorlauf>=Vorlauf-Marketing_Vorverkauf_Monate,Marketing_Vorverkauf/Marketing_Vorverkauf_Monate,0) -> 0 | D11: =IF(D$4+Vorlauf>=Vorlauf-Marketing_Vorverkauf_Monate,Marketing_Vorverkauf/Marketing_Vorverkauf_Monate,0) -> 0 | E11: =IF(E$4+Vorlauf>=Vorlauf-Marketing_Vorverkauf_Monate,Marketing_Vorverkauf/Marketing_Vorverkauf_Monate,0) -> 11666.667 | F11: =IF(F$4+Vorlauf>=Vorlauf-Marketing_Vorverkauf_Monate,Marketing_Vorverkauf/Marketing_Vorverkauf_Monate,0) -> 11666.667 | G11: =IF(G$4+Vorlauf>=Vorlauf-Marketing_Vorverkauf_Monate,Marketing_Vorverkauf/Marketing_Vorverkauf_Monate,0) -> 11666.667 | H11: =Marketing_laufend+IF(H$4<=3,Marketing_Eroeff,0)+Marketing_Pct*Umsatz!C16 -> 9500 | I11: =Marketing_laufend+IF(I$4<=3,Marketing_Eroeff,0)+Marketing_Pct*Umsatz!D16 -> 9500 | J11: =Marketing_laufend+IF(J$4<=3,Marketing_Eroeff,0)+Marketing_Pct*Umsatz!E16 -> 9500 | K11: =Marketing_laufend+IF(K$4<=3,Marketing_Eroeff,0)+Marketing_Pct*Umsatz!F16 -> 3500 | L11: =Marketing_laufend+IF(L$4<=3,Marketing_Eroeff,0)+Marketing_Pct*Umsatz!G16 -> 3500 | M11: =Marketing_laufend+IF(M$4<=3,Marketing_Eroeff,0)+Marketing_Pct*Umsatz!H16 -> 3500 | N11: =Marketing_laufend+IF(N$4<=3,Marketing_Eroeff,0)+Marketing_Pct*Umsatz!I16 -> 3500 | O11: =Marketing_laufend+IF(O$4<=3,Marketing_Eroeff,0)+Marketing_Pct*Umsatz!J16 -> 3500 | ... BO11: =Marketing_laufend+IF(BO$4<=3,Marketing_Eroeff,0)+Marketing_Pct*Umsatz!BJ16 -> 3500 | BQ11: 1
B12: Versicherungen | C12: =IF(C$4<1,0,Versicherung) -> 0 | D12: =IF(D$4<1,0,Versicherung) -> 0 | E12: =IF(E$4<1,0,Versicherung) -> 0 | F12: =IF(F$4<1,0,Versicherung) -> 0 | G12: =IF(G$4<1,0,Versicherung) -> 0 | H12: =IF(H$4<1,0,Versicherung) -> 900 | I12: =IF(I$4<1,0,Versicherung) -> 900 | J12: =IF(J$4<1,0,Versicherung) -> 900 | ... BO12: =IF(BO$4<1,0,Versicherung) -> 900 | BQ12: 0
B13: GEMA / GVL | C13: =IF(C$4<1,0,GEMA) -> 0 | D13: =IF(D$4<1,0,GEMA) -> 0 | E13: =IF(E$4<1,0,GEMA) -> 0 | F13: =IF(F$4<1,0,GEMA) -> 0 | G13: =IF(G$4<1,0,GEMA) -> 0 | H13: =IF(H$4<1,0,GEMA) -> 350 | I13: =IF(I$4<1,0,GEMA) -> 350 | J13: =IF(J$4<1,0,GEMA) -> 350 | ... BO13: =IF(BO$4<1,0,GEMA) -> 350 | BQ13: 1
B14: Studiosoftware / Zutritt | C14: =IF(C$4<1,0,Software) -> 0 | D14: =IF(D$4<1,0,Software) -> 0 | E14: =IF(E$4<1,0,Software) -> 0 | F14: =IF(F$4<1,0,Software) -> 0 | G14: =IF(G$4<1,0,Software) -> 0 | H14: =IF(H$4<1,0,Software) -> 450 | I14: =IF(I$4<1,0,Software) -> 450 | J14: =IF(J$4<1,0,Software) -> 450 | ... BO14: =IF(BO$4<1,0,Software) -> 450 | BQ14: 1
B15: Zahlungsverkehr | C15: 0 | D15: 0 | E15: 0 | F15: 0 | G15: 0 | H15: =Payment_Pct*(Umsatz!C9+Umsatz!C10+Umsatz!C11)*(1+UST) -> 219.19156 | I15: =Payment_Pct*(Umsatz!D9+Umsatz!D10+Umsatz!D11)*(1+UST) -> 276.0305 | J15: =Payment_Pct*(Umsatz!E9+Umsatz!E10+Umsatz!E11)*(1+UST) -> 331.61898 | K15: =Payment_Pct*(Umsatz!F9+Umsatz!F10+Umsatz!F11)*(1+UST) -> 366.32051 | L15: =Payment_Pct*(Umsatz!G9+Umsatz!G10+Umsatz!G11)*(1+UST) -> 402.30514 | M15: =Payment_Pct*(Umsatz!H9+Umsatz!H10+Umsatz!H11)*(1+UST) -> 437.49811 | N15: =Payment_Pct*(Umsatz!I9+Umsatz!I10+Umsatz!I11)*(1+UST) -> 471.91683 | O15: =Payment_Pct*(Umsatz!J9+Umsatz!J10+Umsatz!J11)*(1+UST) -> 505.57834 | ... BO15: =Payment_Pct*(Umsatz!BJ9+Umsatz!BJ10+Umsatz!BJ11)*(1+UST) -> 1030.2846 | BQ15: 0
B16: Steuerberatung / Buchhaltung | C16: =IF(C$4+Vorlauf>=1,StB,0) -> 0 | D16: =IF(D$4+Vorlauf>=1,StB,0) -> 1000 | E16: =IF(E$4+Vorlauf>=1,StB,0) -> 1000 | F16: =IF(F$4+Vorlauf>=1,StB,0) -> 1000 | G16: =IF(G$4+Vorlauf>=1,StB,0) -> 1000 | H16: =IF(H$4+Vorlauf>=1,StB,0) -> 1000 | I16: =IF(I$4+Vorlauf>=1,StB,0) -> 1000 | J16: =IF(J$4+Vorlauf>=1,StB,0) -> 1000 | ... BO16: =IF(BO$4+Vorlauf>=1,StB,0) -> 1000 | BQ16: 1
B17: Reinigung / Hygiene / Verbrauch | C17: =IF(C$4<1,0,Reinigung) -> 0 | D17: =IF(D$4<1,0,Reinigung) -> 0 | E17: =IF(E$4<1,0,Reinigung) -> 0 | F17: =IF(F$4<1,0,Reinigung) -> 0 | G17: =IF(G$4<1,0,Reinigung) -> 0 | H17: =IF(H$4<1,0,Reinigung) -> 2200 | I17: =IF(I$4<1,0,Reinigung) -> 2200 | J17: =IF(J$4<1,0,Reinigung) -> 2200 | ... BO17: =IF(BO$4<1,0,Reinigung) -> 2200 | BQ17: 1
B18: Telekommunikation / IT | C18: =IF(C$4<1,0,Telko) -> 0 | D18: =IF(D$4<1,0,Telko) -> 0 | E18: =IF(E$4<1,0,Telko) -> 0 | F18: =IF(F$4<1,0,Telko) -> 0 | G18: =IF(G$4<1,0,Telko) -> 0 | H18: =IF(H$4<1,0,Telko) -> 250 | I18: =IF(I$4<1,0,Telko) -> 250 | J18: =IF(J$4<1,0,Telko) -> 250 | ... BO18: =IF(BO$4<1,0,Telko) -> 250 | BQ18: 1
B19: Wartung Geräte | C19: =IF(C$4<1,0,Geraetewert*Wartung_Pct/12) -> 0 | D19: =IF(D$4<1,0,Geraetewert*Wartung_Pct/12) -> 0 | E19: =IF(E$4<1,0,Geraetewert*Wartung_Pct/12) -> 0 | F19: =IF(F$4<1,0,Geraetewert*Wartung_Pct/12) -> 0 | G19: =IF(G$4<1,0,Geraetewert*Wartung_Pct/12) -> 0 | H19: =IF(H$4<1,0,Geraetewert*Wartung_Pct/12) -> 2596.65 | I19: =IF(I$4<1,0,Geraetewert*Wartung_Pct/12) -> 2596.65 | J19: =IF(J$4<1,0,Geraetewert*Wartung_Pct/12) -> 2596.65 | ... BO19: =IF(BO$4<1,0,Geraetewert*Wartung_Pct/12) -> 2596.65 | BQ19: 1
B20: Instandhaltung Gebäude/Technik | C20: =IF(C$4<1,0,Flaeche*Instand_m2/12) -> 0 | D20: =IF(D$4<1,0,Flaeche*Instand_m2/12) -> 0 | E20: =IF(E$4<1,0,Flaeche*Instand_m2/12) -> 0 | F20: =IF(F$4<1,0,Flaeche*Instand_m2/12) -> 0 | G20: =IF(G$4<1,0,Flaeche*Instand_m2/12) -> 0 | H20: =IF(H$4<1,0,Flaeche*Instand_m2/12) -> 658.46667 | I20: =IF(I$4<1,0,Flaeche*Instand_m2/12) -> 658.46667 | J20: =IF(J$4<1,0,Flaeche*Instand_m2/12) -> 658.46667 | ... BO20: =IF(BO$4<1,0,Flaeche*Instand_m2/12) -> 658.46667 | BQ20: 1
B21: Sonstiges | C21: =IF(C$4<1,0,Sonstiges) -> 0 | D21: =IF(D$4<1,0,Sonstiges) -> 0 | E21: =IF(E$4<1,0,Sonstiges) -> 0 | F21: =IF(F$4<1,0,Sonstiges) -> 0 | G21: =IF(G$4<1,0,Sonstiges) -> 0 | H21: =IF(H$4<1,0,Sonstiges) -> 1500 | I21: =IF(I$4<1,0,Sonstiges) -> 1500 | J21: =IF(J$4<1,0,Sonstiges) -> 1500 | ... BO21: =IF(BO$4<1,0,Sonstiges) -> 1500 | BQ21: 1
B22: Wareneinsatz Getränke/Shakes | C22: 0 | D22: 0 | E22: 0 | F22: 0 | G22: 0 | H22: =Umsatz!C18 -> 419.64706 | I22: =Umsatz!D18 -> 551.59129 | J22: =Umsatz!E18 -> 680.63276 | K22: =Umsatz!F18 -> 786.66724 | L22: =Umsatz!G18 -> 870.2009 | M22: =Umsatz!H18 -> 951.89681 | N22: =Umsatz!I18 -> 1031.7954 | O22: =Umsatz!J18 -> 1109.9363 | ... BO22: =Umsatz!BJ18 -> 2218.4874 | BQ22: 1
B23: Kosten gesamt (netto) | C23: =SUM(C7:C22) -> 0 | D23: =SUM(D7:D22) -> 1000 | E23: =SUM(E7:E22) -> 16912.167 | F23: =SUM(F7:F22) -> 42020.667 | G23: =SUM(G7:G22) -> 49298.667 | H23: =SUM(H7:H22) -> 77220.279 | I23: =SUM(I7:I22) -> 77409.062 | J23: =SUM(J7:J22) -> 77593.692 | ... BO23: =SUM(BO7:BO22) -> 82193.194
B24: davon vorsteuerfähig | C24: =SUMPRODUCT(C7:C22,$BQ$7:$BQ$22)-IF(UST_Miete=0,C8+C9,0) -> 0 | D24: =SUMPRODUCT(D7:D22,$BQ$7:$BQ$22)-IF(UST_Miete=0,D8+D9,0) -> 1000 | E24: =SUMPRODUCT(E7:E22,$BQ$7:$BQ$22)-IF(UST_Miete=0,E8+E9,0) -> 12666.667 | F24: =SUMPRODUCT(F7:F22,$BQ$7:$BQ$22)-IF(UST_Miete=0,F8+F9,0) -> 33408.367 | G24: =SUMPRODUCT(G7:G22,$BQ$7:$BQ$22)-IF(UST_Miete=0,G8+G9,0) -> 33408.367 | H24: =SUMPRODUCT(H7:H22,$BQ$7:$BQ$22)-IF(UST_Miete=0,H8+H9,0) -> 47568.064 | I24: =SUMPRODUCT(I7:I22,$BQ$7:$BQ$22)-IF(UST_Miete=0,I8+I9,0) -> 47700.008 | J24: =SUMPRODUCT(J7:J22,$BQ$7:$BQ$22)-IF(UST_Miete=0,J8+J9,0) -> 47829.049 | ... BO24: =SUMPRODUCT(BO7:BO22,$BQ$7:$BQ$22)-IF(UST_Miete=0,BO8+BO9,0) -> 44751.014
B25: Vorsteuer auf Kosten | C25: =C24*UST -> 0 | D25: =D24*UST -> 190 | E25: =E24*UST -> 2406.6667 | F25: =F24*UST -> 6347.5897 | G25: =G24*UST -> 6347.5897 | H25: =H24*UST -> 9037.9321 | I25: =I24*UST -> 9063.0015 | J25: =J24*UST -> 9087.5194 | ... BO25: =BO24*UST -> 8502.6927
B26: Vorsteuer-Flag je Zeile in Spalte BQ (1 = Vorsteuer abziehbar)
B28: Jahreswerte (netto; Jahr 1 inkl. Vorlauf)
B29: Jahr | C29: 1 | D29: 2 | E29: 3 | F29: 4 | G29: 5
B30: Personal (AG-Brutto inkl. Sozialabgaben) | C30: =SUMIF(Ko_Jahr,C$29,$C7:$BO7) -> 371144.39 | D30: =SUMIF(Ko_Jahr,D$29,$C7:$BO7) -> 395715.9 | E30: =SUMIF(Ko_Jahr,E$29,$C7:$BO7) -> 405608.79 | F30: =SUMIF(Ko_Jahr,F$29,$C7:$BO7) -> 415749.01 | G30: =SUMIF(Ko_Jahr,G$29,$C7:$BO7) -> 426142.74
B31: Kaltmiete | C31: =SUMIF(Ko_Jahr,C$29,$C8:$BO8) -> 235072.6 | D31: =SUMIF(Ko_Jahr,D$29,$C8:$BO8) -> 205520.62 | E31: =SUMIF(Ko_Jahr,E$29,$C8:$BO8) -> 209631.03 | F31: =SUMIF(Ko_Jahr,F$29,$C8:$BO8) -> 213823.65 | G31: =SUMIF(Ko_Jahr,G$29,$C8:$BO8) -> 218100.12
B32: Betriebskosten | C32: =SUMIF(Ko_Jahr,C$29,$C9:$BO9) -> 55311.2 | D32: =SUMIF(Ko_Jahr,D$29,$C9:$BO9) -> 47409.6 | E32: =SUMIF(Ko_Jahr,E$29,$C9:$BO9) -> 47409.6 | F32: =SUMIF(Ko_Jahr,F$29,$C9:$BO9) -> 47409.6 | G32: =SUMIF(Ko_Jahr,G$29,$C9:$BO9) -> 47409.6
B33: Energie und Wasser | C33: =SUMIF(Ko_Jahr,C$29,$C10:$BO10) -> 94819.2 | D33: =SUMIF(Ko_Jahr,D$29,$C10:$BO10) -> 94819.2 | E33: =SUMIF(Ko_Jahr,E$29,$C10:$BO10) -> 94819.2 | F33: =SUMIF(Ko_Jahr,F$29,$C10:$BO10) -> 94819.2 | G33: =SUMIF(Ko_Jahr,G$29,$C10:$BO10) -> 94819.2
B34: Marketing (laufend, Eröffnung, Vorverkauf) | C34: =SUMIF(Ko_Jahr,C$29,$C11:$BO11) -> 95000 | D34: =SUMIF(Ko_Jahr,D$29,$C11:$BO11) -> 42000 | E34: =SUMIF(Ko_Jahr,E$29,$C11:$BO11) -> 42000 | F34: =SUMIF(Ko_Jahr,F$29,$C11:$BO11) -> 42000 | G34: =SUMIF(Ko_Jahr,G$29,$C11:$BO11) -> 42000
B35: Versicherungen | C35: =SUMIF(Ko_Jahr,C$29,$C12:$BO12) -> 10800 | D35: =SUMIF(Ko_Jahr,D$29,$C12:$BO12) -> 10800 | E35: =SUMIF(Ko_Jahr,E$29,$C12:$BO12) -> 10800 | F35: =SUMIF(Ko_Jahr,F$29,$C12:$BO12) -> 10800 | G35: =SUMIF(Ko_Jahr,G$29,$C12:$BO12) -> 10800
B36: GEMA / GVL | C36: =SUMIF(Ko_Jahr,C$29,$C13:$BO13) -> 4200 | D36: =SUMIF(Ko_Jahr,D$29,$C13:$BO13) -> 4200 | E36: =SUMIF(Ko_Jahr,E$29,$C13:$BO13) -> 4200 | F36: =SUMIF(Ko_Jahr,F$29,$C13:$BO13) -> 4200 | G36: =SUMIF(Ko_Jahr,G$29,$C13:$BO13) -> 4200
B37: Studiosoftware / Zutritt | C37: =SUMIF(Ko_Jahr,C$29,$C14:$BO14) -> 5400 | D37: =SUMIF(Ko_Jahr,D$29,$C14:$BO14) -> 5400 | E37: =SUMIF(Ko_Jahr,E$29,$C14:$BO14) -> 5400 | F37: =SUMIF(Ko_Jahr,F$29,$C14:$BO14) -> 5400 | G37: =SUMIF(Ko_Jahr,G$29,$C14:$BO14) -> 5400
B38: Zahlungsverkehr | C38: =SUMIF(Ko_Jahr,C$29,$C15:$BO15) -> 5354.8196 | D38: =SUMIF(Ko_Jahr,D$29,$C15:$BO15) -> 9442.7492 | E38: =SUMIF(Ko_Jahr,E$29,$C15:$BO15) -> 11800.88 | F38: =SUMIF(Ko_Jahr,F$29,$C15:$BO15) -> 12143.024 | G38: =SUMIF(Ko_Jahr,G$29,$C15:$BO15) -> 12363.416
B39: Steuerberatung / Buchhaltung | C39: =SUMIF(Ko_Jahr,C$29,$C16:$BO16) -> 16000 | D39: =SUMIF(Ko_Jahr,D$29,$C16:$BO16) -> 12000 | E39: =SUMIF(Ko_Jahr,E$29,$C16:$BO16) -> 12000 | F39: =SUMIF(Ko_Jahr,F$29,$C16:$BO16) -> 12000 | G39: =SUMIF(Ko_Jahr,G$29,$C16:$BO16) -> 12000
B40: Reinigung / Hygiene / Verbrauch | C40: =SUMIF(Ko_Jahr,C$29,$C17:$BO17) -> 26400 | D40: =SUMIF(Ko_Jahr,D$29,$C17:$BO17) -> 26400 | E40: =SUMIF(Ko_Jahr,E$29,$C17:$BO17) -> 26400 | F40: =SUMIF(Ko_Jahr,F$29,$C17:$BO17) -> 26400 | G40: =SUMIF(Ko_Jahr,G$29,$C17:$BO17) -> 26400
B41: Telekommunikation / IT | C41: =SUMIF(Ko_Jahr,C$29,$C18:$BO18) -> 3000 | D41: =SUMIF(Ko_Jahr,D$29,$C18:$BO18) -> 3000 | E41: =SUMIF(Ko_Jahr,E$29,$C18:$BO18) -> 3000 | F41: =SUMIF(Ko_Jahr,F$29,$C18:$BO18) -> 3000 | G41: =SUMIF(Ko_Jahr,G$29,$C18:$BO18) -> 3000
... B45: Wareneinsatz Getränke/Shakes | C45: =SUMIF(Ko_Jahr,C$29,$C22:$BO22) -> 11589.701 | D45: =SUMIF(Ko_Jahr,D$29,$C22:$BO22) -> 21232.177 | E45: =SUMIF(Ko_Jahr,E$29,$C22:$BO22) -> 26296.968 | F45: =SUMIF(Ko_Jahr,F$29,$C22:$BO22) -> 26621.849 | G45: =SUMIF(Ko_Jahr,G$29,$C22:$BO22) -> 26621.849
...

Sheet Finanzierung
B1: Finanzierungsplan – Mittelverwendung, Mittelherkunft, Tilgungspläne
B3: Mittelverwendung | C3: EUR | D3: Anteil
B4: Geräte und Import | C4: =SUMIF(Inv_Gruppe,"Geräte",Inv_Betrag) -> 623196 | D4: =C4/$C$13 -> 0.2376268
B5: Ausbau (Mieterausbau, Lüftung, Böden, Spiegel, Brandschutz) | C5: =SUMIF(Inv_Gruppe,"Ausbau",Inv_Betrag) -> 851788 | D5: =C5/$C$13 -> 0.32478972
B6: Sanitärinstallation | C6: =SUMIF(Inv_Gruppe,"Sanitär",Inv_Betrag) -> 39800 | D6: =C6/$C$13 -> 0.015175878
B7: Planung und Genehmigung | C7: =SUMIF(Inv_Gruppe,"Planung",Inv_Betrag) -> 106991 | D7: =C7/$C$13 -> 0.04079604
B8: Sonstiges (Zutritt, Software, Kleinmaterial) | C8: =SUMIF(Inv_Gruppe,"Sonstiges",Inv_Betrag) -> 32000 | D8: =C8/$C$13 -> 0.012201711
B9: Unvorhergesehenes | C9: =SUMIF(Inv_Gruppe,"Reserve",Inv_Betrag) -> 165378 | D9: =C9/$C$13 -> 0.063059205
B10: Mietkaution | C10: =SUMIF(Inv_Gruppe,"Kaution",Inv_Betrag) -> 85930 | D10: =C10/$C$13 -> 0.032765407
B11: Gründung und Beratung | C11: =SUMIF(Inv_Gruppe,"Gründung",Inv_Betrag) -> 7500 | D11: =C11/$C$13 -> 0.002859776
B12: Anlaufreserve / Betriebsmittel (24 Monate) | C12: =Reserve -> 710000 | D12: =C12/$C$13 -> 0.27072546
B13: Kapitalbedarf gesamt | C13: =SUM(C4:C12) -> 2622583 | D13: =C13/C13 -> 1
B14: Kontrolle: = Blatt Investition | C14: =C13-Kapitalbedarf -> 0
B16: Mittelherkunft | C16: EUR | D16: Anteil
B17: Eigenkapital (Bareinlage) | C17: =EK -> 150000 | D17: =C17/$C$22 -> 0.057195521
B18: =Darl1_Name -> MBG Baden-Württemberg – stille Beteiligung Existenzgründung (wirtschaftliches Eigenkapital) | C18: =Darl1_Betrag -> 250000 | D18: =C18/$C$22 -> 0.095325868
B19: =Darl2_Name -> KfW ERP-Förderkredit Gründung und Nachfolge (077), 100 % Garantie Bürgschaftsbank | C19: =Darl2_Betrag -> 500000 | D19: =C19/$C$22 -> 0.19065174
